INFO 2025-04-21 02:29:33,809 autoreload Watching for file changes with StatReloader
INFO 2025-04-21 02:32:29,914 autoreload /app/borrowers/models.py changed, reloading.
INFO 2025-04-21 02:32:30,634 autoreload Watching for file changes with StatReloader
INFO 2025-04-21 02:34:20,501 autoreload /app/documents/models.py changed, reloading.
INFO 2025-04-21 02:34:21,183 autoreload Watching for file changes with StatReloader
INFO 2025-04-21 02:38:02,407 autoreload /app/applications/models.py changed, reloading.
INFO 2025-04-21 02:38:03,162 autoreload Watching for file changes with StatReloader
INFO 2025-04-21 02:38:11,786 autoreload /app/borrowers/models.py changed, reloading.
INFO 2025-04-21 02:38:12,310 autoreload Watching for file changes with StatReloader
INFO 2025-04-21 02:38:19,872 autoreload /app/brokers/models.py changed, reloading.
INFO 2025-04-21 02:38:20,484 autoreload Watching for file changes with StatReloader
INFO 2025-04-21 02:38:27,065 autoreload /app/brokers/models.py changed, reloading.
INFO 2025-04-21 02:38:27,628 autoreload Watching for file changes with StatReloader
INFO 2025-04-21 02:39:11,776 autoreload Watching for file changes with StatReloader
INFO 2025-04-21 02:39:39,515 autoreload /app/documents/models.py changed, reloading.
INFO 2025-04-21 02:39:40,219 autoreload Watching for file changes with StatReloader
INFO 2025-04-21 02:39:46,848 autoreload Watching for file changes with StatReloader
INFO 2025-04-21 02:40:25,418 autoreload /app/borrowers/models.py changed, reloading.
INFO 2025-04-21 02:40:26,148 autoreload Watching for file changes with StatReloader
INFO 2025-04-21 02:41:44,080 autoreload /app/borrowers/models.py changed, reloading.
INFO 2025-04-21 02:41:44,800 autoreload Watching for file changes with StatReloader
INFO 2025-04-21 02:42:00,810 autoreload /app/borrowers/models.py changed, reloading.
INFO 2025-04-21 02:42:01,554 autoreload Watching for file changes with StatReloader
INFO 2025-04-21 02:42:10,064 basehttp "OPTIONS /api/users/auth/register/ HTTP/1.1" 200 0
INFO 2025-04-21 02:42:10,078 views Registration attempt with data: {'email': 'fanhongyuan897@gmail.com', 'first_name': 'Hongyuan', 'last_name': 'Fan', 'phone': '0415455625', 'role': 'client', 'password': '12345'}
ERROR 2025-04-21 02:42:10,104 views Exception during registration: column users_user.username does not exist
LINE 1: SELECT 1 AS "a" FROM "users_user" WHERE "users_user"."userna...
                                                ^
Traceback (most recent call last):
  File "/usr/local/lib/python3.9/site-packages/django/db/backends/utils.py", line 89, in _execute
    return self.cursor.execute(sql, params)
psycopg2.errors.UndefinedColumn: column users_user.username does not exist
LINE 1: SELECT 1 AS "a" FROM "users_user" WHERE "users_user"."userna...
                                                ^


The above exception was the direct cause of the following exception:

Traceback (most recent call last):
  File "/app/users/views.py", line 63, in post
    if serializer.is_valid():
  File "/usr/local/lib/python3.9/site-packages/rest_framework/serializers.py", line 225, in is_valid
    self._validated_data = self.run_validation(self.initial_data)
  File "/usr/local/lib/python3.9/site-packages/rest_framework/serializers.py", line 444, in run_validation
    value = self.to_internal_value(data)
  File "/usr/local/lib/python3.9/site-packages/rest_framework/serializers.py", line 501, in to_internal_value
    validated_value = field.run_validation(primitive_value)
  File "/usr/local/lib/python3.9/site-packages/rest_framework/fields.py", line 757, in run_validation
    return super().run_validation(data)
  File "/usr/local/lib/python3.9/site-packages/rest_framework/fields.py", line 539, in run_validation
    self.run_validators(value)
  File "/usr/local/lib/python3.9/site-packages/rest_framework/fields.py", line 551, in run_validators
    validator(value, self)
  File "/usr/local/lib/python3.9/site-packages/rest_framework/validators.py", line 86, in __call__
    if qs_exists(queryset):
  File "/usr/local/lib/python3.9/site-packages/rest_framework/validators.py", line 23, in qs_exists
    return queryset.exists()
  File "/usr/local/lib/python3.9/site-packages/django/db/models/query.py", line 1241, in exists
    return self.query.has_results(using=self.db)
  File "/usr/local/lib/python3.9/site-packages/django/db/models/sql/query.py", line 598, in has_results
    return compiler.has_results()
  File "/usr/local/lib/python3.9/site-packages/django/db/models/sql/compiler.py", line 1530, in has_results
    return bool(self.execute_sql(SINGLE))
  File "/usr/local/lib/python3.9/site-packages/django/db/models/sql/compiler.py", line 1562, in execute_sql
    cursor.execute(sql, params)
  File "/usr/local/lib/python3.9/site-packages/django/db/backends/utils.py", line 102, in execute
    return super().execute(sql, params)
  File "/usr/local/lib/python3.9/site-packages/django/db/backends/utils.py", line 67, in execute
    return self._execute_with_wrappers(
  File "/usr/local/lib/python3.9/site-packages/django/db/backends/utils.py", line 80, in _execute_with_wrappers
    return executor(sql, params, many, context)
  File "/usr/local/lib/python3.9/site-packages/django/db/backends/utils.py", line 89, in _execute
    return self.cursor.execute(sql, params)
  File "/usr/local/lib/python3.9/site-packages/django/db/utils.py", line 91, in __exit__
    raise dj_exc_value.with_traceback(traceback) from exc_value
  File "/usr/local/lib/python3.9/site-packages/django/db/backends/utils.py", line 89, in _execute
    return self.cursor.execute(sql, params)
django.db.utils.ProgrammingError: column users_user.username does not exist
LINE 1: SELECT 1 AS "a" FROM "users_user" WHERE "users_user"."userna...
                                                ^

ERROR 2025-04-21 02:42:10,121 log Internal Server Error: /api/users/auth/register/
ERROR 2025-04-21 02:42:10,121 basehttp "POST /api/users/auth/register/ HTTP/1.1" 500 186
INFO 2025-04-21 02:42:23,825 autoreload /app/borrowers/models.py changed, reloading.
INFO 2025-04-21 02:42:24,520 autoreload Watching for file changes with StatReloader
INFO 2025-04-21 02:43:25,855 autoreload /app/documents/models.py changed, reloading.
INFO 2025-04-21 02:43:26,577 autoreload Watching for file changes with StatReloader
INFO 2025-04-21 02:44:59,927 autoreload /app/documents/models.py changed, reloading.
INFO 2025-04-21 02:45:00,603 autoreload Watching for file changes with StatReloader
INFO 2025-04-21 02:45:14,428 autoreload /app/documents/models.py changed, reloading.
INFO 2025-04-21 02:45:15,092 autoreload Watching for file changes with StatReloader
INFO 2025-04-21 02:46:10,207 autoreload /app/documents/models.py changed, reloading.
INFO 2025-04-21 02:46:10,884 autoreload Watching for file changes with StatReloader
INFO 2025-04-21 02:46:28,772 autoreload /app/applications/models.py changed, reloading.
INFO 2025-04-21 02:46:29,344 autoreload Watching for file changes with StatReloader
INFO 2025-04-21 02:46:41,075 autoreload /app/applications/models.py changed, reloading.
INFO 2025-04-21 02:46:41,607 autoreload Watching for file changes with StatReloader
INFO 2025-04-21 02:46:58,443 autoreload /app/brokers/models.py changed, reloading.
INFO 2025-04-21 02:46:59,028 autoreload Watching for file changes with StatReloader
INFO 2025-04-21 02:47:15,929 autoreload /app/brokers/models.py changed, reloading.
INFO 2025-04-21 02:47:16,573 autoreload Watching for file changes with StatReloader
INFO 2025-04-21 02:47:26,246 autoreload /app/brokers/models.py changed, reloading.
INFO 2025-04-21 02:47:26,765 autoreload Watching for file changes with StatReloader
INFO 2025-04-21 02:48:44,353 autoreload /app/users/models.py changed, reloading.
INFO 2025-04-21 02:48:45,011 autoreload Watching for file changes with StatReloader
INFO 2025-04-21 02:49:05,019 autoreload /app/users/admin.py changed, reloading.
INFO 2025-04-21 02:49:05,697 autoreload Watching for file changes with StatReloader
INFO 2025-04-21 02:49:20,577 autoreload /app/users/serializers.py changed, reloading.
INFO 2025-04-21 02:49:21,231 autoreload Watching for file changes with StatReloader
INFO 2025-04-21 02:49:30,926 autoreload /app/users/serializers.py changed, reloading.
INFO 2025-04-21 02:49:31,464 autoreload Watching for file changes with StatReloader
INFO 2025-04-21 02:49:54,562 autoreload /app/users/views.py changed, reloading.
INFO 2025-04-21 02:49:55,210 autoreload Watching for file changes with StatReloader
INFO 2025-04-21 02:51:59,069 autoreload /app/borrowers/models.py changed, reloading.
INFO 2025-04-21 02:51:59,721 autoreload Watching for file changes with StatReloader
INFO 2025-04-21 02:52:11,483 autoreload /app/borrowers/models.py changed, reloading.
INFO 2025-04-21 02:52:12,017 autoreload Watching for file changes with StatReloader
INFO 2025-04-21 02:52:29,919 autoreload /app/borrowers/models.py changed, reloading.
INFO 2025-04-21 02:52:30,503 autoreload Watching for file changes with StatReloader
INFO 2025-04-21 02:52:47,377 autoreload /app/borrowers/models.py changed, reloading.
INFO 2025-04-21 02:52:48,013 autoreload Watching for file changes with StatReloader
INFO 2025-04-21 02:53:27,636 autoreload /app/borrowers/models.py changed, reloading.
INFO 2025-04-21 02:53:28,278 autoreload Watching for file changes with StatReloader
INFO 2025-04-21 02:53:57,518 autoreload /app/documents/models.py changed, reloading.
INFO 2025-04-21 02:53:58,162 autoreload Watching for file changes with StatReloader
INFO 2025-04-21 02:54:08,868 autoreload /app/documents/models.py changed, reloading.
INFO 2025-04-21 02:54:09,393 autoreload Watching for file changes with StatReloader
INFO 2025-04-21 02:54:15,944 autoreload /app/documents/models.py changed, reloading.
INFO 2025-04-21 02:54:16,589 autoreload Watching for file changes with StatReloader
INFO 2025-04-21 02:55:07,439 autoreload /app/applications/models.py changed, reloading.
INFO 2025-04-21 02:55:08,086 autoreload Watching for file changes with StatReloader
INFO 2025-04-21 02:55:53,838 autoreload /app/applications/models.py changed, reloading.
INFO 2025-04-21 02:55:54,491 autoreload Watching for file changes with StatReloader
INFO 2025-04-21 02:56:04,174 autoreload /app/applications/models.py changed, reloading.
INFO 2025-04-21 02:56:04,711 autoreload Watching for file changes with StatReloader
INFO 2025-04-21 02:56:53,555 autoreload /app/applications/models.py changed, reloading.
INFO 2025-04-21 02:56:54,211 autoreload Watching for file changes with StatReloader
INFO 2025-04-21 02:57:01,863 autoreload /app/applications/models.py changed, reloading.
INFO 2025-04-21 02:57:02,537 autoreload Watching for file changes with StatReloader
INFO 2025-04-21 02:57:17,337 autoreload /app/applications/models.py changed, reloading.
INFO 2025-04-21 02:57:17,871 autoreload Watching for file changes with StatReloader
INFO 2025-04-21 02:57:26,464 autoreload /app/applications/models.py changed, reloading.
INFO 2025-04-21 02:57:27,010 autoreload Watching for file changes with StatReloader
INFO 2025-04-21 02:59:11,001 views Registration attempt with data: {'email': 'fanhongyuan897@gmail.com', 'first_name': 'Hongyuan', 'last_name': 'Fan', 'phone': '0415455625', 'role': 'client', 'password': '12345'}
ERROR 2025-04-21 02:59:11,186 views Exception during registration: column "username" of relation "users_user" does not exist
LINE 1: ...active", "date_joined", "email", "role", "phone", "username"...
                                                             ^
Traceback (most recent call last):
  File "/usr/local/lib/python3.9/site-packages/django/db/backends/utils.py", line 89, in _execute
    return self.cursor.execute(sql, params)
psycopg2.errors.UndefinedColumn: column "username" of relation "users_user" does not exist
LINE 1: ...active", "date_joined", "email", "role", "phone", "username"...
                                                             ^


The above exception was the direct cause of the following exception:

Traceback (most recent call last):
  File "/app/users/views.py", line 62, in post
    user = serializer.save()
  File "/usr/local/lib/python3.9/site-packages/rest_framework/serializers.py", line 210, in save
    self.instance = self.create(validated_data)
  File "/app/users/serializers.py", line 30, in create
    user.save()
  File "/usr/local/lib/python3.9/site-packages/django/contrib/auth/base_user.py", line 76, in save
    super().save(*args, **kwargs)
  File "/usr/local/lib/python3.9/site-packages/django/db/models/base.py", line 814, in save
    self.save_base(
  File "/usr/local/lib/python3.9/site-packages/django/db/models/base.py", line 877, in save_base
    updated = self._save_table(
  File "/usr/local/lib/python3.9/site-packages/django/db/models/base.py", line 1020, in _save_table
    results = self._do_insert(
  File "/usr/local/lib/python3.9/site-packages/django/db/models/base.py", line 1061, in _do_insert
    return manager._insert(
  File "/usr/local/lib/python3.9/site-packages/django/db/models/manager.py", line 87, in manager_method
    return getattr(self.get_queryset(), name)(*args, **kwargs)
  File "/usr/local/lib/python3.9/site-packages/django/db/models/query.py", line 1805, in _insert
    return query.get_compiler(using=using).execute_sql(returning_fields)
  File "/usr/local/lib/python3.9/site-packages/django/db/models/sql/compiler.py", line 1822, in execute_sql
    cursor.execute(sql, params)
  File "/usr/local/lib/python3.9/site-packages/django/db/backends/utils.py", line 102, in execute
    return super().execute(sql, params)
  File "/usr/local/lib/python3.9/site-packages/django/db/backends/utils.py", line 67, in execute
    return self._execute_with_wrappers(
  File "/usr/local/lib/python3.9/site-packages/django/db/backends/utils.py", line 80, in _execute_with_wrappers
    return executor(sql, params, many, context)
  File "/usr/local/lib/python3.9/site-packages/django/db/backends/utils.py", line 89, in _execute
    return self.cursor.execute(sql, params)
  File "/usr/local/lib/python3.9/site-packages/django/db/utils.py", line 91, in __exit__
    raise dj_exc_value.with_traceback(traceback) from exc_value
  File "/usr/local/lib/python3.9/site-packages/django/db/backends/utils.py", line 89, in _execute
    return self.cursor.execute(sql, params)
django.db.utils.ProgrammingError: column "username" of relation "users_user" does not exist
LINE 1: ...active", "date_joined", "email", "role", "phone", "username"...
                                                             ^

ERROR 2025-04-21 02:59:11,194 log Internal Server Error: /api/users/auth/register/
ERROR 2025-04-21 02:59:11,194 basehttp "POST /api/users/auth/register/ HTTP/1.1" 500 226
INFO 2025-04-21 11:06:47,573 views Login attempt for email: admin@example.com
WARNING 2025-04-21 11:06:47,736 log Unauthorized: /api/users/auth/login/
INFO 2025-04-21 11:06:48,233 views Login attempt for email: admin@example.com
INFO 2025-04-21 11:06:50,945 views Registration attempt with data: {'email': 'admin@example.com', 'password': 'newpassword123', 'first_name': 'Duplicate', 'last_name': 'User', 'role': 'client'}
ERROR 2025-04-21 11:06:50,947 views Registration validation errors: {'email': [ErrorDetail(string='user with this email address already exists.', code='unique')]}
WARNING 2025-04-21 11:06:50,947 log Bad Request: /api/users/auth/register/
INFO 2025-04-21 11:06:51,450 views Registration attempt with data: {'email': 'newuser@example.com', 'password': 'newpassword123', 'first_name': 'New', 'last_name': 'User', 'role': 'client'}
ERROR 2025-04-21 11:06:51,625 views Exception during registration: no such table: users_notificationpreference
Traceback (most recent call last):
  File "/Users/hongyuanfan/Library/Python/3.9/lib/python/site-packages/django/db/backends/utils.py", line 89, in _execute
    return self.cursor.execute(sql, params)
  File "/Users/hongyuanfan/Library/Python/3.9/lib/python/site-packages/django/db/backends/sqlite3/base.py", line 328, in execute
    return super().execute(query, params)
sqlite3.OperationalError: no such table: users_notificationpreference

The above exception was the direct cause of the following exception:

Traceback (most recent call last):
  File "/Users/hongyuanfan/Desktop/LoanAPPV3/backenddjango/users/views.py", line 66, in post
    user = serializer.save()
  File "/Users/hongyuanfan/Library/Python/3.9/lib/python/site-packages/rest_framework/serializers.py", line 212, in save
    self.instance = self.create(validated_data)
  File "/Users/hongyuanfan/Desktop/LoanAPPV3/backenddjango/users/serializers.py", line 33, in create
    NotificationPreference.objects.create(user=user)
  File "/Users/hongyuanfan/Library/Python/3.9/lib/python/site-packages/django/db/models/manager.py", line 87, in manager_method
    return getattr(self.get_queryset(), name)(*args, **kwargs)
  File "/Users/hongyuanfan/Library/Python/3.9/lib/python/site-packages/django/db/models/query.py", line 658, in create
    obj.save(force_insert=True, using=self.db)
  File "/Users/hongyuanfan/Library/Python/3.9/lib/python/site-packages/django/db/models/base.py", line 814, in save
    self.save_base(
  File "/Users/hongyuanfan/Library/Python/3.9/lib/python/site-packages/django/db/models/base.py", line 877, in save_base
    updated = self._save_table(
  File "/Users/hongyuanfan/Library/Python/3.9/lib/python/site-packages/django/db/models/base.py", line 1020, in _save_table
    results = self._do_insert(
  File "/Users/hongyuanfan/Library/Python/3.9/lib/python/site-packages/django/db/models/base.py", line 1061, in _do_insert
    return manager._insert(
  File "/Users/hongyuanfan/Library/Python/3.9/lib/python/site-packages/django/db/models/manager.py", line 87, in manager_method
    return getattr(self.get_queryset(), name)(*args, **kwargs)
  File "/Users/hongyuanfan/Library/Python/3.9/lib/python/site-packages/django/db/models/query.py", line 1805, in _insert
    return query.get_compiler(using=using).execute_sql(returning_fields)
  File "/Users/hongyuanfan/Library/Python/3.9/lib/python/site-packages/django/db/models/sql/compiler.py", line 1822, in execute_sql
    cursor.execute(sql, params)
  File "/Users/hongyuanfan/Library/Python/3.9/lib/python/site-packages/django/db/backends/utils.py", line 67, in execute
    return self._execute_with_wrappers(
  File "/Users/hongyuanfan/Library/Python/3.9/lib/python/site-packages/django/db/backends/utils.py", line 80, in _execute_with_wrappers
    return executor(sql, params, many, context)
  File "/Users/hongyuanfan/Library/Python/3.9/lib/python/site-packages/django/db/backends/utils.py", line 89, in _execute
    return self.cursor.execute(sql, params)
  File "/Users/hongyuanfan/Library/Python/3.9/lib/python/site-packages/django/db/utils.py", line 91, in __exit__
    raise dj_exc_value.with_traceback(traceback) from exc_value
  File "/Users/hongyuanfan/Library/Python/3.9/lib/python/site-packages/django/db/backends/utils.py", line 89, in _execute
    return self.cursor.execute(sql, params)
  File "/Users/hongyuanfan/Library/Python/3.9/lib/python/site-packages/django/db/backends/sqlite3/base.py", line 328, in execute
    return super().execute(query, params)
django.db.utils.OperationalError: no such table: users_notificationpreference
ERROR 2025-04-21 11:06:51,637 log Internal Server Error: /api/users/auth/register/
INFO 2025-04-21 11:07:23,177 views Login attempt for email: admin@example.com
WARNING 2025-04-21 11:07:23,341 log Unauthorized: /api/users/auth/login/
INFO 2025-04-21 11:07:23,839 views Login attempt for email: admin@example.com
INFO 2025-04-21 11:07:26,582 views Registration attempt with data: {'email': 'admin@example.com', 'password': 'newpassword123', 'first_name': 'Duplicate', 'last_name': 'User', 'role': 'client'}
ERROR 2025-04-21 11:07:26,584 views Registration validation errors: {'email': [ErrorDetail(string='user with this email address already exists.', code='unique')]}
WARNING 2025-04-21 11:07:26,584 log Bad Request: /api/users/auth/register/
INFO 2025-04-21 11:07:27,075 views Registration attempt with data: {'email': 'newuser@example.com', 'password': 'newpassword123', 'first_name': 'New', 'last_name': 'User', 'role': 'client'}
ERROR 2025-04-21 11:07:27,244 views Exception during registration: no such table: users_notificationpreference
Traceback (most recent call last):
  File "/Users/hongyuanfan/Library/Python/3.9/lib/python/site-packages/django/db/backends/utils.py", line 89, in _execute
    return self.cursor.execute(sql, params)
  File "/Users/hongyuanfan/Library/Python/3.9/lib/python/site-packages/django/db/backends/sqlite3/base.py", line 328, in execute
    return super().execute(query, params)
sqlite3.OperationalError: no such table: users_notificationpreference

The above exception was the direct cause of the following exception:

Traceback (most recent call last):
  File "/Users/hongyuanfan/Desktop/LoanAPPV3/backenddjango/users/views.py", line 66, in post
    user = serializer.save()
  File "/Users/hongyuanfan/Library/Python/3.9/lib/python/site-packages/rest_framework/serializers.py", line 212, in save
    self.instance = self.create(validated_data)
  File "/Users/hongyuanfan/Desktop/LoanAPPV3/backenddjango/users/serializers.py", line 33, in create
    NotificationPreference.objects.create(user=user)
  File "/Users/hongyuanfan/Library/Python/3.9/lib/python/site-packages/django/db/models/manager.py", line 87, in manager_method
    return getattr(self.get_queryset(), name)(*args, **kwargs)
  File "/Users/hongyuanfan/Library/Python/3.9/lib/python/site-packages/django/db/models/query.py", line 658, in create
    obj.save(force_insert=True, using=self.db)
  File "/Users/hongyuanfan/Library/Python/3.9/lib/python/site-packages/django/db/models/base.py", line 814, in save
    self.save_base(
  File "/Users/hongyuanfan/Library/Python/3.9/lib/python/site-packages/django/db/models/base.py", line 877, in save_base
    updated = self._save_table(
  File "/Users/hongyuanfan/Library/Python/3.9/lib/python/site-packages/django/db/models/base.py", line 1020, in _save_table
    results = self._do_insert(
  File "/Users/hongyuanfan/Library/Python/3.9/lib/python/site-packages/django/db/models/base.py", line 1061, in _do_insert
    return manager._insert(
  File "/Users/hongyuanfan/Library/Python/3.9/lib/python/site-packages/django/db/models/manager.py", line 87, in manager_method
    return getattr(self.get_queryset(), name)(*args, **kwargs)
  File "/Users/hongyuanfan/Library/Python/3.9/lib/python/site-packages/django/db/models/query.py", line 1805, in _insert
    return query.get_compiler(using=using).execute_sql(returning_fields)
  File "/Users/hongyuanfan/Library/Python/3.9/lib/python/site-packages/django/db/models/sql/compiler.py", line 1822, in execute_sql
    cursor.execute(sql, params)
  File "/Users/hongyuanfan/Library/Python/3.9/lib/python/site-packages/django/db/backends/utils.py", line 67, in execute
    return self._execute_with_wrappers(
  File "/Users/hongyuanfan/Library/Python/3.9/lib/python/site-packages/django/db/backends/utils.py", line 80, in _execute_with_wrappers
    return executor(sql, params, many, context)
  File "/Users/hongyuanfan/Library/Python/3.9/lib/python/site-packages/django/db/backends/utils.py", line 89, in _execute
    return self.cursor.execute(sql, params)
  File "/Users/hongyuanfan/Library/Python/3.9/lib/python/site-packages/django/db/utils.py", line 91, in __exit__
    raise dj_exc_value.with_traceback(traceback) from exc_value
  File "/Users/hongyuanfan/Library/Python/3.9/lib/python/site-packages/django/db/backends/utils.py", line 89, in _execute
    return self.cursor.execute(sql, params)
  File "/Users/hongyuanfan/Library/Python/3.9/lib/python/site-packages/django/db/backends/sqlite3/base.py", line 328, in execute
    return super().execute(query, params)
django.db.utils.OperationalError: no such table: users_notificationpreference
ERROR 2025-04-21 11:07:27,257 log Internal Server Error: /api/users/auth/register/
INFO 2025-04-21 11:12:37,979 views Login attempt for email: admin@example.com
WARNING 2025-04-21 11:12:38,143 log Unauthorized: /api/users/auth/login/
INFO 2025-04-21 11:12:38,638 views Login attempt for email: admin@example.com
INFO 2025-04-21 11:12:41,332 views Registration attempt with data: {'email': 'admin@example.com', 'password': 'newpassword123', 'first_name': 'Duplicate', 'last_name': 'User', 'role': 'client'}
ERROR 2025-04-21 11:12:41,334 views Registration validation errors: {'email': [ErrorDetail(string='user with this email address already exists.', code='unique')]}
WARNING 2025-04-21 11:12:41,334 log Bad Request: /api/users/auth/register/
INFO 2025-04-21 11:12:41,833 views Registration attempt with data: {'email': 'newuser@example.com', 'password': 'newpassword123', 'first_name': 'New', 'last_name': 'User', 'role': 'client'}
WARNING 2025-04-21 11:12:43,023 log Forbidden: /api/users/users/
INFO 2025-04-21 11:13:39,548 views Login attempt for email: admin@example.com
WARNING 2025-04-21 11:13:39,714 log Unauthorized: /api/users/auth/login/
INFO 2025-04-21 11:13:40,208 views Login attempt for email: admin@example.com
INFO 2025-04-21 11:13:42,902 views Registration attempt with data: {'email': 'admin@example.com', 'password': 'newpassword123', 'first_name': 'Duplicate', 'last_name': 'User', 'role': 'client'}
ERROR 2025-04-21 11:13:42,904 views Registration validation errors: {'email': [ErrorDetail(string='user with this email address already exists.', code='unique')]}
WARNING 2025-04-21 11:13:42,904 log Bad Request: /api/users/auth/register/
INFO 2025-04-21 11:13:43,398 views Registration attempt with data: {'email': 'newuser@example.com', 'password': 'newpassword123', 'first_name': 'New', 'last_name': 'User', 'role': 'client'}
WARNING 2025-04-21 11:13:44,553 log Forbidden: /api/users/users/
WARNING 2025-04-21 11:24:57,258 log Not Found: /api/applications/applications/99999/
WARNING 2025-04-21 11:24:57,259 log Bad Request: /api/applications/applications/
ERROR 2025-04-21 11:24:57,264 log Internal Server Error: /api/applications/applications/1/
Traceback (most recent call last):
  File "/Users/hongyuanfan/Library/Python/3.9/lib/python/site-packages/django/core/handlers/exception.py", line 55, in inner
    response = get_response(request)
  File "/Users/hongyuanfan/Library/Python/3.9/lib/python/site-packages/django/core/handlers/base.py", line 197, in _get_response
    response = wrapped_callback(request, *callback_args, **callback_kwargs)
  File "/Users/hongyuanfan/Library/Python/3.9/lib/python/site-packages/django/views/decorators/csrf.py", line 56, in wrapper_view
    return view_func(*args, **kwargs)
  File "/Users/hongyuanfan/Library/Python/3.9/lib/python/site-packages/rest_framework/viewsets.py", line 125, in view
    return self.dispatch(request, *args, **kwargs)
  File "/Users/hongyuanfan/Library/Python/3.9/lib/python/site-packages/rest_framework/views.py", line 509, in dispatch
    response = self.handle_exception(exc)
  File "/Users/hongyuanfan/Library/Python/3.9/lib/python/site-packages/rest_framework/views.py", line 469, in handle_exception
    self.raise_uncaught_exception(exc)
  File "/Users/hongyuanfan/Library/Python/3.9/lib/python/site-packages/rest_framework/views.py", line 480, in raise_uncaught_exception
    raise exc
  File "/Users/hongyuanfan/Library/Python/3.9/lib/python/site-packages/rest_framework/views.py", line 506, in dispatch
    response = handler(request, *args, **kwargs)
  File "/Users/hongyuanfan/Library/Python/3.9/lib/python/site-packages/rest_framework/mixins.py", line 82, in partial_update
    return self.update(request, *args, **kwargs)
  File "/Users/hongyuanfan/Library/Python/3.9/lib/python/site-packages/rest_framework/mixins.py", line 67, in update
    serializer.is_valid(raise_exception=True)
  File "/Users/hongyuanfan/Library/Python/3.9/lib/python/site-packages/rest_framework/serializers.py", line 227, in is_valid
    self._validated_data = self.run_validation(self.initial_data)
  File "/Users/hongyuanfan/Library/Python/3.9/lib/python/site-packages/rest_framework/serializers.py", line 426, in run_validation
    value = self.to_internal_value(data)
  File "/Users/hongyuanfan/Library/Python/3.9/lib/python/site-packages/rest_framework/serializers.py", line 479, in to_internal_value
    for field in fields:
  File "/Users/hongyuanfan/Library/Python/3.9/lib/python/site-packages/rest_framework/serializers.py", line 362, in _writable_fields
    for field in self.fields.values():
  File "/Users/hongyuanfan/Library/Python/3.9/lib/python/site-packages/django/utils/functional.py", line 57, in __get__
    res = instance.__dict__[self.name] = self.func(instance)
  File "/Users/hongyuanfan/Library/Python/3.9/lib/python/site-packages/rest_framework/serializers.py", line 356, in fields
    for key, value in self.get_fields().items():
  File "/Users/hongyuanfan/Library/Python/3.9/lib/python/site-packages/rest_framework/serializers.py", line 1076, in get_fields
    field_class, field_kwargs = self.build_field(
  File "/Users/hongyuanfan/Library/Python/3.9/lib/python/site-packages/rest_framework/serializers.py", line 1222, in build_field
    return self.build_unknown_field(field_name, model_class)
  File "/Users/hongyuanfan/Library/Python/3.9/lib/python/site-packages/rest_framework/serializers.py", line 1340, in build_unknown_field
    raise ImproperlyConfigured(
django.core.exceptions.ImproperlyConfigured: Field name `property` is not valid for model `Application`.
ERROR 2025-04-21 11:24:57,941 log Internal Server Error: /api/applications/applications/
Traceback (most recent call last):
  File "/Users/hongyuanfan/Library/Python/3.9/lib/python/site-packages/django/core/handlers/exception.py", line 55, in inner
    response = get_response(request)
  File "/Users/hongyuanfan/Library/Python/3.9/lib/python/site-packages/django/core/handlers/base.py", line 197, in _get_response
    response = wrapped_callback(request, *callback_args, **callback_kwargs)
  File "/Users/hongyuanfan/Library/Python/3.9/lib/python/site-packages/django/views/decorators/csrf.py", line 56, in wrapper_view
    return view_func(*args, **kwargs)
  File "/Users/hongyuanfan/Library/Python/3.9/lib/python/site-packages/rest_framework/viewsets.py", line 125, in view
    return self.dispatch(request, *args, **kwargs)
  File "/Users/hongyuanfan/Library/Python/3.9/lib/python/site-packages/rest_framework/views.py", line 509, in dispatch
    response = self.handle_exception(exc)
  File "/Users/hongyuanfan/Library/Python/3.9/lib/python/site-packages/rest_framework/views.py", line 469, in handle_exception
    self.raise_uncaught_exception(exc)
  File "/Users/hongyuanfan/Library/Python/3.9/lib/python/site-packages/rest_framework/views.py", line 480, in raise_uncaught_exception
    raise exc
  File "/Users/hongyuanfan/Library/Python/3.9/lib/python/site-packages/rest_framework/views.py", line 506, in dispatch
    response = handler(request, *args, **kwargs)
  File "/Users/hongyuanfan/Library/Python/3.9/lib/python/site-packages/rest_framework/mixins.py", line 43, in list
    return self.get_paginated_response(serializer.data)
  File "/Users/hongyuanfan/Library/Python/3.9/lib/python/site-packages/rest_framework/serializers.py", line 768, in data
    ret = super().data
  File "/Users/hongyuanfan/Library/Python/3.9/lib/python/site-packages/rest_framework/serializers.py", line 253, in data
    self._data = self.to_representation(self.instance)
  File "/Users/hongyuanfan/Library/Python/3.9/lib/python/site-packages/rest_framework/serializers.py", line 686, in to_representation
    return [
  File "/Users/hongyuanfan/Library/Python/3.9/lib/python/site-packages/rest_framework/serializers.py", line 687, in <listcomp>
    self.child.to_representation(item) for item in iterable
  File "/Users/hongyuanfan/Library/Python/3.9/lib/python/site-packages/rest_framework/serializers.py", line 507, in to_representation
    for field in fields:
  File "/Users/hongyuanfan/Library/Python/3.9/lib/python/site-packages/rest_framework/serializers.py", line 368, in _readable_fields
    for field in self.fields.values():
  File "/Users/hongyuanfan/Library/Python/3.9/lib/python/site-packages/django/utils/functional.py", line 57, in __get__
    res = instance.__dict__[self.name] = self.func(instance)
  File "/Users/hongyuanfan/Library/Python/3.9/lib/python/site-packages/rest_framework/serializers.py", line 356, in fields
    for key, value in self.get_fields().items():
  File "/Users/hongyuanfan/Library/Python/3.9/lib/python/site-packages/rest_framework/serializers.py", line 1076, in get_fields
    field_class, field_kwargs = self.build_field(
  File "/Users/hongyuanfan/Library/Python/3.9/lib/python/site-packages/rest_framework/serializers.py", line 1222, in build_field
    return self.build_unknown_field(field_name, model_class)
  File "/Users/hongyuanfan/Library/Python/3.9/lib/python/site-packages/rest_framework/serializers.py", line 1340, in build_unknown_field
    raise ImproperlyConfigured(
django.core.exceptions.ImproperlyConfigured: Field name `property` is not valid for model `Application`.
INFO 2025-04-21 11:24:59,270 views Login attempt for email: admin@example.com
ERROR 2025-04-21 11:24:59,475 log Internal Server Error: /api/applications/applications/
Traceback (most recent call last):
  File "/Users/hongyuanfan/Library/Python/3.9/lib/python/site-packages/django/core/handlers/exception.py", line 55, in inner
    response = get_response(request)
  File "/Users/hongyuanfan/Library/Python/3.9/lib/python/site-packages/django/core/handlers/base.py", line 197, in _get_response
    response = wrapped_callback(request, *callback_args, **callback_kwargs)
  File "/Users/hongyuanfan/Library/Python/3.9/lib/python/site-packages/django/views/decorators/csrf.py", line 56, in wrapper_view
    return view_func(*args, **kwargs)
  File "/Users/hongyuanfan/Library/Python/3.9/lib/python/site-packages/rest_framework/viewsets.py", line 125, in view
    return self.dispatch(request, *args, **kwargs)
  File "/Users/hongyuanfan/Library/Python/3.9/lib/python/site-packages/rest_framework/views.py", line 509, in dispatch
    response = self.handle_exception(exc)
  File "/Users/hongyuanfan/Library/Python/3.9/lib/python/site-packages/rest_framework/views.py", line 469, in handle_exception
    self.raise_uncaught_exception(exc)
  File "/Users/hongyuanfan/Library/Python/3.9/lib/python/site-packages/rest_framework/views.py", line 480, in raise_uncaught_exception
    raise exc
  File "/Users/hongyuanfan/Library/Python/3.9/lib/python/site-packages/rest_framework/views.py", line 506, in dispatch
    response = handler(request, *args, **kwargs)
  File "/Users/hongyuanfan/Library/Python/3.9/lib/python/site-packages/rest_framework/mixins.py", line 43, in list
    return self.get_paginated_response(serializer.data)
  File "/Users/hongyuanfan/Library/Python/3.9/lib/python/site-packages/rest_framework/serializers.py", line 768, in data
    ret = super().data
  File "/Users/hongyuanfan/Library/Python/3.9/lib/python/site-packages/rest_framework/serializers.py", line 253, in data
    self._data = self.to_representation(self.instance)
  File "/Users/hongyuanfan/Library/Python/3.9/lib/python/site-packages/rest_framework/serializers.py", line 686, in to_representation
    return [
  File "/Users/hongyuanfan/Library/Python/3.9/lib/python/site-packages/rest_framework/serializers.py", line 687, in <listcomp>
    self.child.to_representation(item) for item in iterable
  File "/Users/hongyuanfan/Library/Python/3.9/lib/python/site-packages/rest_framework/serializers.py", line 507, in to_representation
    for field in fields:
  File "/Users/hongyuanfan/Library/Python/3.9/lib/python/site-packages/rest_framework/serializers.py", line 368, in _readable_fields
    for field in self.fields.values():
  File "/Users/hongyuanfan/Library/Python/3.9/lib/python/site-packages/django/utils/functional.py", line 57, in __get__
    res = instance.__dict__[self.name] = self.func(instance)
  File "/Users/hongyuanfan/Library/Python/3.9/lib/python/site-packages/rest_framework/serializers.py", line 356, in fields
    for key, value in self.get_fields().items():
  File "/Users/hongyuanfan/Library/Python/3.9/lib/python/site-packages/rest_framework/serializers.py", line 1076, in get_fields
    field_class, field_kwargs = self.build_field(
  File "/Users/hongyuanfan/Library/Python/3.9/lib/python/site-packages/rest_framework/serializers.py", line 1222, in build_field
    return self.build_unknown_field(field_name, model_class)
  File "/Users/hongyuanfan/Library/Python/3.9/lib/python/site-packages/rest_framework/serializers.py", line 1340, in build_unknown_field
    raise ImproperlyConfigured(
django.core.exceptions.ImproperlyConfigured: Field name `property` is not valid for model `Application`.
ERROR 2025-04-21 11:25:00,135 log Internal Server Error: /api/applications/applications/
Traceback (most recent call last):
  File "/Users/hongyuanfan/Library/Python/3.9/lib/python/site-packages/django/core/handlers/exception.py", line 55, in inner
    response = get_response(request)
  File "/Users/hongyuanfan/Library/Python/3.9/lib/python/site-packages/django/core/handlers/base.py", line 197, in _get_response
    response = wrapped_callback(request, *callback_args, **callback_kwargs)
  File "/Users/hongyuanfan/Library/Python/3.9/lib/python/site-packages/django/views/decorators/csrf.py", line 56, in wrapper_view
    return view_func(*args, **kwargs)
  File "/Users/hongyuanfan/Library/Python/3.9/lib/python/site-packages/rest_framework/viewsets.py", line 125, in view
    return self.dispatch(request, *args, **kwargs)
  File "/Users/hongyuanfan/Library/Python/3.9/lib/python/site-packages/rest_framework/views.py", line 509, in dispatch
    response = self.handle_exception(exc)
  File "/Users/hongyuanfan/Library/Python/3.9/lib/python/site-packages/rest_framework/views.py", line 469, in handle_exception
    self.raise_uncaught_exception(exc)
  File "/Users/hongyuanfan/Library/Python/3.9/lib/python/site-packages/rest_framework/views.py", line 480, in raise_uncaught_exception
    raise exc
  File "/Users/hongyuanfan/Library/Python/3.9/lib/python/site-packages/rest_framework/views.py", line 506, in dispatch
    response = handler(request, *args, **kwargs)
  File "/Users/hongyuanfan/Library/Python/3.9/lib/python/site-packages/rest_framework/mixins.py", line 18, in create
    serializer.is_valid(raise_exception=True)
  File "/Users/hongyuanfan/Library/Python/3.9/lib/python/site-packages/rest_framework/serializers.py", line 227, in is_valid
    self._validated_data = self.run_validation(self.initial_data)
  File "/Users/hongyuanfan/Library/Python/3.9/lib/python/site-packages/rest_framework/serializers.py", line 426, in run_validation
    value = self.to_internal_value(data)
  File "/Users/hongyuanfan/Library/Python/3.9/lib/python/site-packages/rest_framework/serializers.py", line 483, in to_internal_value
    validated_value = field.run_validation(primitive_value)
  File "/Users/hongyuanfan/Library/Python/3.9/lib/python/site-packages/rest_framework/serializers.py", line 618, in run_validation
    value = self.to_internal_value(data)
  File "/Users/hongyuanfan/Library/Python/3.9/lib/python/site-packages/rest_framework/serializers.py", line 666, in to_internal_value
    validated = self.child.run_validation(item)
  File "/Users/hongyuanfan/Library/Python/3.9/lib/python/site-packages/rest_framework/serializers.py", line 426, in run_validation
    value = self.to_internal_value(data)
  File "/Users/hongyuanfan/Library/Python/3.9/lib/python/site-packages/rest_framework/serializers.py", line 479, in to_internal_value
    for field in fields:
  File "/Users/hongyuanfan/Library/Python/3.9/lib/python/site-packages/rest_framework/serializers.py", line 362, in _writable_fields
    for field in self.fields.values():
  File "/Users/hongyuanfan/Library/Python/3.9/lib/python/site-packages/django/utils/functional.py", line 57, in __get__
    res = instance.__dict__[self.name] = self.func(instance)
  File "/Users/hongyuanfan/Library/Python/3.9/lib/python/site-packages/rest_framework/serializers.py", line 356, in fields
    for key, value in self.get_fields().items():
  File "/Users/hongyuanfan/Library/Python/3.9/lib/python/site-packages/rest_framework/serializers.py", line 1076, in get_fields
    field_class, field_kwargs = self.build_field(
  File "/Users/hongyuanfan/Library/Python/3.9/lib/python/site-packages/rest_framework/serializers.py", line 1222, in build_field
    return self.build_unknown_field(field_name, model_class)
  File "/Users/hongyuanfan/Library/Python/3.9/lib/python/site-packages/rest_framework/serializers.py", line 1340, in build_unknown_field
    raise ImproperlyConfigured(
django.core.exceptions.ImproperlyConfigured: Field name `dob` is not valid for model `Borrower`.
ERROR 2025-04-21 11:25:00,818 log Internal Server Error: /api/applications/applications/
Traceback (most recent call last):
  File "/Users/hongyuanfan/Library/Python/3.9/lib/python/site-packages/django/core/handlers/exception.py", line 55, in inner
    response = get_response(request)
  File "/Users/hongyuanfan/Library/Python/3.9/lib/python/site-packages/django/core/handlers/base.py", line 197, in _get_response
    response = wrapped_callback(request, *callback_args, **callback_kwargs)
  File "/Users/hongyuanfan/Library/Python/3.9/lib/python/site-packages/django/views/decorators/csrf.py", line 56, in wrapper_view
    return view_func(*args, **kwargs)
  File "/Users/hongyuanfan/Library/Python/3.9/lib/python/site-packages/rest_framework/viewsets.py", line 125, in view
    return self.dispatch(request, *args, **kwargs)
  File "/Users/hongyuanfan/Library/Python/3.9/lib/python/site-packages/rest_framework/views.py", line 509, in dispatch
    response = self.handle_exception(exc)
  File "/Users/hongyuanfan/Library/Python/3.9/lib/python/site-packages/rest_framework/views.py", line 469, in handle_exception
    self.raise_uncaught_exception(exc)
  File "/Users/hongyuanfan/Library/Python/3.9/lib/python/site-packages/rest_framework/views.py", line 480, in raise_uncaught_exception
    raise exc
  File "/Users/hongyuanfan/Library/Python/3.9/lib/python/site-packages/rest_framework/views.py", line 506, in dispatch
    response = handler(request, *args, **kwargs)
  File "/Users/hongyuanfan/Library/Python/3.9/lib/python/site-packages/rest_framework/mixins.py", line 18, in create
    serializer.is_valid(raise_exception=True)
  File "/Users/hongyuanfan/Library/Python/3.9/lib/python/site-packages/rest_framework/serializers.py", line 227, in is_valid
    self._validated_data = self.run_validation(self.initial_data)
  File "/Users/hongyuanfan/Library/Python/3.9/lib/python/site-packages/rest_framework/serializers.py", line 426, in run_validation
    value = self.to_internal_value(data)
  File "/Users/hongyuanfan/Library/Python/3.9/lib/python/site-packages/rest_framework/serializers.py", line 483, in to_internal_value
    validated_value = field.run_validation(primitive_value)
  File "/Users/hongyuanfan/Library/Python/3.9/lib/python/site-packages/rest_framework/serializers.py", line 618, in run_validation
    value = self.to_internal_value(data)
  File "/Users/hongyuanfan/Library/Python/3.9/lib/python/site-packages/rest_framework/serializers.py", line 666, in to_internal_value
    validated = self.child.run_validation(item)
  File "/Users/hongyuanfan/Library/Python/3.9/lib/python/site-packages/rest_framework/serializers.py", line 426, in run_validation
    value = self.to_internal_value(data)
  File "/Users/hongyuanfan/Library/Python/3.9/lib/python/site-packages/rest_framework/serializers.py", line 479, in to_internal_value
    for field in fields:
  File "/Users/hongyuanfan/Library/Python/3.9/lib/python/site-packages/rest_framework/serializers.py", line 362, in _writable_fields
    for field in self.fields.values():
  File "/Users/hongyuanfan/Library/Python/3.9/lib/python/site-packages/django/utils/functional.py", line 57, in __get__
    res = instance.__dict__[self.name] = self.func(instance)
  File "/Users/hongyuanfan/Library/Python/3.9/lib/python/site-packages/rest_framework/serializers.py", line 356, in fields
    for key, value in self.get_fields().items():
  File "/Users/hongyuanfan/Library/Python/3.9/lib/python/site-packages/rest_framework/serializers.py", line 1076, in get_fields
    field_class, field_kwargs = self.build_field(
  File "/Users/hongyuanfan/Library/Python/3.9/lib/python/site-packages/rest_framework/serializers.py", line 1222, in build_field
    return self.build_unknown_field(field_name, model_class)
  File "/Users/hongyuanfan/Library/Python/3.9/lib/python/site-packages/rest_framework/serializers.py", line 1340, in build_unknown_field
    raise ImproperlyConfigured(
django.core.exceptions.ImproperlyConfigured: Field name `dob` is not valid for model `Borrower`.
ERROR 2025-04-21 11:25:01,487 log Internal Server Error: /api/applications/applications/
Traceback (most recent call last):
  File "/Users/hongyuanfan/Library/Python/3.9/lib/python/site-packages/django/core/handlers/exception.py", line 55, in inner
    response = get_response(request)
  File "/Users/hongyuanfan/Library/Python/3.9/lib/python/site-packages/django/core/handlers/base.py", line 197, in _get_response
    response = wrapped_callback(request, *callback_args, **callback_kwargs)
  File "/Users/hongyuanfan/Library/Python/3.9/lib/python/site-packages/django/views/decorators/csrf.py", line 56, in wrapper_view
    return view_func(*args, **kwargs)
  File "/Users/hongyuanfan/Library/Python/3.9/lib/python/site-packages/rest_framework/viewsets.py", line 125, in view
    return self.dispatch(request, *args, **kwargs)
  File "/Users/hongyuanfan/Library/Python/3.9/lib/python/site-packages/rest_framework/views.py", line 509, in dispatch
    response = self.handle_exception(exc)
  File "/Users/hongyuanfan/Library/Python/3.9/lib/python/site-packages/rest_framework/views.py", line 469, in handle_exception
    self.raise_uncaught_exception(exc)
  File "/Users/hongyuanfan/Library/Python/3.9/lib/python/site-packages/rest_framework/views.py", line 480, in raise_uncaught_exception
    raise exc
  File "/Users/hongyuanfan/Library/Python/3.9/lib/python/site-packages/rest_framework/views.py", line 506, in dispatch
    response = handler(request, *args, **kwargs)
  File "/Users/hongyuanfan/Library/Python/3.9/lib/python/site-packages/rest_framework/mixins.py", line 43, in list
    return self.get_paginated_response(serializer.data)
  File "/Users/hongyuanfan/Library/Python/3.9/lib/python/site-packages/rest_framework/serializers.py", line 768, in data
    ret = super().data
  File "/Users/hongyuanfan/Library/Python/3.9/lib/python/site-packages/rest_framework/serializers.py", line 253, in data
    self._data = self.to_representation(self.instance)
  File "/Users/hongyuanfan/Library/Python/3.9/lib/python/site-packages/rest_framework/serializers.py", line 686, in to_representation
    return [
  File "/Users/hongyuanfan/Library/Python/3.9/lib/python/site-packages/rest_framework/serializers.py", line 687, in <listcomp>
    self.child.to_representation(item) for item in iterable
  File "/Users/hongyuanfan/Library/Python/3.9/lib/python/site-packages/rest_framework/serializers.py", line 507, in to_representation
    for field in fields:
  File "/Users/hongyuanfan/Library/Python/3.9/lib/python/site-packages/rest_framework/serializers.py", line 368, in _readable_fields
    for field in self.fields.values():
  File "/Users/hongyuanfan/Library/Python/3.9/lib/python/site-packages/django/utils/functional.py", line 57, in __get__
    res = instance.__dict__[self.name] = self.func(instance)
  File "/Users/hongyuanfan/Library/Python/3.9/lib/python/site-packages/rest_framework/serializers.py", line 356, in fields
    for key, value in self.get_fields().items():
  File "/Users/hongyuanfan/Library/Python/3.9/lib/python/site-packages/rest_framework/serializers.py", line 1076, in get_fields
    field_class, field_kwargs = self.build_field(
  File "/Users/hongyuanfan/Library/Python/3.9/lib/python/site-packages/rest_framework/serializers.py", line 1222, in build_field
    return self.build_unknown_field(field_name, model_class)
  File "/Users/hongyuanfan/Library/Python/3.9/lib/python/site-packages/rest_framework/serializers.py", line 1340, in build_unknown_field
    raise ImproperlyConfigured(
django.core.exceptions.ImproperlyConfigured: Field name `property` is not valid for model `Application`.
WARNING 2025-04-21 11:25:02,814 log Bad Request: /api/applications/applications/1/add_fee/
WARNING 2025-04-21 11:25:04,142 log Bad Request: /api/applications/applications/1/add_repayment/
ERROR 2025-04-21 11:25:04,798 log Internal Server Error: /api/applications/applications/1/
Traceback (most recent call last):
  File "/Users/hongyuanfan/Library/Python/3.9/lib/python/site-packages/django/core/handlers/exception.py", line 55, in inner
    response = get_response(request)
  File "/Users/hongyuanfan/Library/Python/3.9/lib/python/site-packages/django/core/handlers/base.py", line 197, in _get_response
    response = wrapped_callback(request, *callback_args, **callback_kwargs)
  File "/Users/hongyuanfan/Library/Python/3.9/lib/python/site-packages/django/views/decorators/csrf.py", line 56, in wrapper_view
    return view_func(*args, **kwargs)
  File "/Users/hongyuanfan/Library/Python/3.9/lib/python/site-packages/rest_framework/viewsets.py", line 125, in view
    return self.dispatch(request, *args, **kwargs)
  File "/Users/hongyuanfan/Library/Python/3.9/lib/python/site-packages/rest_framework/views.py", line 509, in dispatch
    response = self.handle_exception(exc)
  File "/Users/hongyuanfan/Library/Python/3.9/lib/python/site-packages/rest_framework/views.py", line 469, in handle_exception
    self.raise_uncaught_exception(exc)
  File "/Users/hongyuanfan/Library/Python/3.9/lib/python/site-packages/rest_framework/views.py", line 480, in raise_uncaught_exception
    raise exc
  File "/Users/hongyuanfan/Library/Python/3.9/lib/python/site-packages/rest_framework/views.py", line 506, in dispatch
    response = handler(request, *args, **kwargs)
  File "/Users/hongyuanfan/Library/Python/3.9/lib/python/site-packages/rest_framework/mixins.py", line 56, in retrieve
    return Response(serializer.data)
  File "/Users/hongyuanfan/Library/Python/3.9/lib/python/site-packages/rest_framework/serializers.py", line 555, in data
    ret = super().data
  File "/Users/hongyuanfan/Library/Python/3.9/lib/python/site-packages/rest_framework/serializers.py", line 253, in data
    self._data = self.to_representation(self.instance)
  File "/Users/hongyuanfan/Library/Python/3.9/lib/python/site-packages/rest_framework/serializers.py", line 507, in to_representation
    for field in fields:
  File "/Users/hongyuanfan/Library/Python/3.9/lib/python/site-packages/rest_framework/serializers.py", line 368, in _readable_fields
    for field in self.fields.values():
  File "/Users/hongyuanfan/Library/Python/3.9/lib/python/site-packages/django/utils/functional.py", line 57, in __get__
    res = instance.__dict__[self.name] = self.func(instance)
  File "/Users/hongyuanfan/Library/Python/3.9/lib/python/site-packages/rest_framework/serializers.py", line 356, in fields
    for key, value in self.get_fields().items():
  File "/Users/hongyuanfan/Library/Python/3.9/lib/python/site-packages/rest_framework/serializers.py", line 1076, in get_fields
    field_class, field_kwargs = self.build_field(
  File "/Users/hongyuanfan/Library/Python/3.9/lib/python/site-packages/rest_framework/serializers.py", line 1222, in build_field
    return self.build_unknown_field(field_name, model_class)
  File "/Users/hongyuanfan/Library/Python/3.9/lib/python/site-packages/rest_framework/serializers.py", line 1340, in build_unknown_field
    raise ImproperlyConfigured(
django.core.exceptions.ImproperlyConfigured: Field name `property` is not valid for model `Application`.
ERROR 2025-04-21 11:25:05,483 log Internal Server Error: /api/applications/applications/
Traceback (most recent call last):
  File "/Users/hongyuanfan/Library/Python/3.9/lib/python/site-packages/django/core/handlers/exception.py", line 55, in inner
    response = get_response(request)
  File "/Users/hongyuanfan/Library/Python/3.9/lib/python/site-packages/django/core/handlers/base.py", line 197, in _get_response
    response = wrapped_callback(request, *callback_args, **callback_kwargs)
  File "/Users/hongyuanfan/Library/Python/3.9/lib/python/site-packages/django/views/decorators/csrf.py", line 56, in wrapper_view
    return view_func(*args, **kwargs)
  File "/Users/hongyuanfan/Library/Python/3.9/lib/python/site-packages/rest_framework/viewsets.py", line 125, in view
    return self.dispatch(request, *args, **kwargs)
  File "/Users/hongyuanfan/Library/Python/3.9/lib/python/site-packages/rest_framework/views.py", line 509, in dispatch
    response = self.handle_exception(exc)
  File "/Users/hongyuanfan/Library/Python/3.9/lib/python/site-packages/rest_framework/views.py", line 469, in handle_exception
    self.raise_uncaught_exception(exc)
  File "/Users/hongyuanfan/Library/Python/3.9/lib/python/site-packages/rest_framework/views.py", line 480, in raise_uncaught_exception
    raise exc
  File "/Users/hongyuanfan/Library/Python/3.9/lib/python/site-packages/rest_framework/views.py", line 506, in dispatch
    response = handler(request, *args, **kwargs)
  File "/Users/hongyuanfan/Library/Python/3.9/lib/python/site-packages/rest_framework/mixins.py", line 43, in list
    return self.get_paginated_response(serializer.data)
  File "/Users/hongyuanfan/Library/Python/3.9/lib/python/site-packages/rest_framework/serializers.py", line 768, in data
    ret = super().data
  File "/Users/hongyuanfan/Library/Python/3.9/lib/python/site-packages/rest_framework/serializers.py", line 253, in data
    self._data = self.to_representation(self.instance)
  File "/Users/hongyuanfan/Library/Python/3.9/lib/python/site-packages/rest_framework/serializers.py", line 686, in to_representation
    return [
  File "/Users/hongyuanfan/Library/Python/3.9/lib/python/site-packages/rest_framework/serializers.py", line 687, in <listcomp>
    self.child.to_representation(item) for item in iterable
  File "/Users/hongyuanfan/Library/Python/3.9/lib/python/site-packages/rest_framework/serializers.py", line 507, in to_representation
    for field in fields:
  File "/Users/hongyuanfan/Library/Python/3.9/lib/python/site-packages/rest_framework/serializers.py", line 368, in _readable_fields
    for field in self.fields.values():
  File "/Users/hongyuanfan/Library/Python/3.9/lib/python/site-packages/django/utils/functional.py", line 57, in __get__
    res = instance.__dict__[self.name] = self.func(instance)
  File "/Users/hongyuanfan/Library/Python/3.9/lib/python/site-packages/rest_framework/serializers.py", line 356, in fields
    for key, value in self.get_fields().items():
  File "/Users/hongyuanfan/Library/Python/3.9/lib/python/site-packages/rest_framework/serializers.py", line 1076, in get_fields
    field_class, field_kwargs = self.build_field(
  File "/Users/hongyuanfan/Library/Python/3.9/lib/python/site-packages/rest_framework/serializers.py", line 1222, in build_field
    return self.build_unknown_field(field_name, model_class)
  File "/Users/hongyuanfan/Library/Python/3.9/lib/python/site-packages/rest_framework/serializers.py", line 1340, in build_unknown_field
    raise ImproperlyConfigured(
django.core.exceptions.ImproperlyConfigured: Field name `property` is not valid for model `Application`.
ERROR 2025-04-21 11:25:06,156 log Internal Server Error: /api/applications/applications/
Traceback (most recent call last):
  File "/Users/hongyuanfan/Library/Python/3.9/lib/python/site-packages/django/core/handlers/exception.py", line 55, in inner
    response = get_response(request)
  File "/Users/hongyuanfan/Library/Python/3.9/lib/python/site-packages/django/core/handlers/base.py", line 197, in _get_response
    response = wrapped_callback(request, *callback_args, **callback_kwargs)
  File "/Users/hongyuanfan/Library/Python/3.9/lib/python/site-packages/django/views/decorators/csrf.py", line 56, in wrapper_view
    return view_func(*args, **kwargs)
  File "/Users/hongyuanfan/Library/Python/3.9/lib/python/site-packages/rest_framework/viewsets.py", line 125, in view
    return self.dispatch(request, *args, **kwargs)
  File "/Users/hongyuanfan/Library/Python/3.9/lib/python/site-packages/rest_framework/views.py", line 509, in dispatch
    response = self.handle_exception(exc)
  File "/Users/hongyuanfan/Library/Python/3.9/lib/python/site-packages/rest_framework/views.py", line 469, in handle_exception
    self.raise_uncaught_exception(exc)
  File "/Users/hongyuanfan/Library/Python/3.9/lib/python/site-packages/rest_framework/views.py", line 480, in raise_uncaught_exception
    raise exc
  File "/Users/hongyuanfan/Library/Python/3.9/lib/python/site-packages/rest_framework/views.py", line 506, in dispatch
    response = handler(request, *args, **kwargs)
  File "/Users/hongyuanfan/Library/Python/3.9/lib/python/site-packages/rest_framework/mixins.py", line 18, in create
    serializer.is_valid(raise_exception=True)
  File "/Users/hongyuanfan/Library/Python/3.9/lib/python/site-packages/rest_framework/serializers.py", line 227, in is_valid
    self._validated_data = self.run_validation(self.initial_data)
  File "/Users/hongyuanfan/Library/Python/3.9/lib/python/site-packages/rest_framework/serializers.py", line 426, in run_validation
    value = self.to_internal_value(data)
  File "/Users/hongyuanfan/Library/Python/3.9/lib/python/site-packages/rest_framework/serializers.py", line 483, in to_internal_value
    validated_value = field.run_validation(primitive_value)
  File "/Users/hongyuanfan/Library/Python/3.9/lib/python/site-packages/rest_framework/serializers.py", line 618, in run_validation
    value = self.to_internal_value(data)
  File "/Users/hongyuanfan/Library/Python/3.9/lib/python/site-packages/rest_framework/serializers.py", line 666, in to_internal_value
    validated = self.child.run_validation(item)
  File "/Users/hongyuanfan/Library/Python/3.9/lib/python/site-packages/rest_framework/serializers.py", line 426, in run_validation
    value = self.to_internal_value(data)
  File "/Users/hongyuanfan/Library/Python/3.9/lib/python/site-packages/rest_framework/serializers.py", line 479, in to_internal_value
    for field in fields:
  File "/Users/hongyuanfan/Library/Python/3.9/lib/python/site-packages/rest_framework/serializers.py", line 362, in _writable_fields
    for field in self.fields.values():
  File "/Users/hongyuanfan/Library/Python/3.9/lib/python/site-packages/django/utils/functional.py", line 57, in __get__
    res = instance.__dict__[self.name] = self.func(instance)
  File "/Users/hongyuanfan/Library/Python/3.9/lib/python/site-packages/rest_framework/serializers.py", line 356, in fields
    for key, value in self.get_fields().items():
  File "/Users/hongyuanfan/Library/Python/3.9/lib/python/site-packages/rest_framework/serializers.py", line 1076, in get_fields
    field_class, field_kwargs = self.build_field(
  File "/Users/hongyuanfan/Library/Python/3.9/lib/python/site-packages/rest_framework/serializers.py", line 1222, in build_field
    return self.build_unknown_field(field_name, model_class)
  File "/Users/hongyuanfan/Library/Python/3.9/lib/python/site-packages/rest_framework/serializers.py", line 1340, in build_unknown_field
    raise ImproperlyConfigured(
django.core.exceptions.ImproperlyConfigured: Field name `dob` is not valid for model `Borrower`.
WARNING 2025-04-21 11:25:06,822 log Not Found: /api/applications/applications/99999/
WARNING 2025-04-21 11:25:06,823 log Bad Request: /api/applications/applications/
ERROR 2025-04-21 11:25:06,824 log Internal Server Error: /api/applications/applications/1/
Traceback (most recent call last):
  File "/Users/hongyuanfan/Library/Python/3.9/lib/python/site-packages/django/core/handlers/exception.py", line 55, in inner
    response = get_response(request)
  File "/Users/hongyuanfan/Library/Python/3.9/lib/python/site-packages/django/core/handlers/base.py", line 197, in _get_response
    response = wrapped_callback(request, *callback_args, **callback_kwargs)
  File "/Users/hongyuanfan/Library/Python/3.9/lib/python/site-packages/django/views/decorators/csrf.py", line 56, in wrapper_view
    return view_func(*args, **kwargs)
  File "/Users/hongyuanfan/Library/Python/3.9/lib/python/site-packages/rest_framework/viewsets.py", line 125, in view
    return self.dispatch(request, *args, **kwargs)
  File "/Users/hongyuanfan/Library/Python/3.9/lib/python/site-packages/rest_framework/views.py", line 509, in dispatch
    response = self.handle_exception(exc)
  File "/Users/hongyuanfan/Library/Python/3.9/lib/python/site-packages/rest_framework/views.py", line 469, in handle_exception
    self.raise_uncaught_exception(exc)
  File "/Users/hongyuanfan/Library/Python/3.9/lib/python/site-packages/rest_framework/views.py", line 480, in raise_uncaught_exception
    raise exc
  File "/Users/hongyuanfan/Library/Python/3.9/lib/python/site-packages/rest_framework/views.py", line 506, in dispatch
    response = handler(request, *args, **kwargs)
  File "/Users/hongyuanfan/Library/Python/3.9/lib/python/site-packages/rest_framework/mixins.py", line 82, in partial_update
    return self.update(request, *args, **kwargs)
  File "/Users/hongyuanfan/Library/Python/3.9/lib/python/site-packages/rest_framework/mixins.py", line 67, in update
    serializer.is_valid(raise_exception=True)
  File "/Users/hongyuanfan/Library/Python/3.9/lib/python/site-packages/rest_framework/serializers.py", line 227, in is_valid
    self._validated_data = self.run_validation(self.initial_data)
  File "/Users/hongyuanfan/Library/Python/3.9/lib/python/site-packages/rest_framework/serializers.py", line 426, in run_validation
    value = self.to_internal_value(data)
  File "/Users/hongyuanfan/Library/Python/3.9/lib/python/site-packages/rest_framework/serializers.py", line 479, in to_internal_value
    for field in fields:
  File "/Users/hongyuanfan/Library/Python/3.9/lib/python/site-packages/rest_framework/serializers.py", line 362, in _writable_fields
    for field in self.fields.values():
  File "/Users/hongyuanfan/Library/Python/3.9/lib/python/site-packages/django/utils/functional.py", line 57, in __get__
    res = instance.__dict__[self.name] = self.func(instance)
  File "/Users/hongyuanfan/Library/Python/3.9/lib/python/site-packages/rest_framework/serializers.py", line 356, in fields
    for key, value in self.get_fields().items():
  File "/Users/hongyuanfan/Library/Python/3.9/lib/python/site-packages/rest_framework/serializers.py", line 1076, in get_fields
    field_class, field_kwargs = self.build_field(
  File "/Users/hongyuanfan/Library/Python/3.9/lib/python/site-packages/rest_framework/serializers.py", line 1222, in build_field
    return self.build_unknown_field(field_name, model_class)
  File "/Users/hongyuanfan/Library/Python/3.9/lib/python/site-packages/rest_framework/serializers.py", line 1340, in build_unknown_field
    raise ImproperlyConfigured(
django.core.exceptions.ImproperlyConfigured: Field name `property` is not valid for model `Application`.
ERROR 2025-04-21 11:25:10,153 log Internal Server Error: /api/applications/applications/
Traceback (most recent call last):
  File "/Users/hongyuanfan/Library/Python/3.9/lib/python/site-packages/django/core/handlers/exception.py", line 55, in inner
    response = get_response(request)
  File "/Users/hongyuanfan/Library/Python/3.9/lib/python/site-packages/django/core/handlers/base.py", line 197, in _get_response
    response = wrapped_callback(request, *callback_args, **callback_kwargs)
  File "/Users/hongyuanfan/Library/Python/3.9/lib/python/site-packages/django/views/decorators/csrf.py", line 56, in wrapper_view
    return view_func(*args, **kwargs)
  File "/Users/hongyuanfan/Library/Python/3.9/lib/python/site-packages/rest_framework/viewsets.py", line 125, in view
    return self.dispatch(request, *args, **kwargs)
  File "/Users/hongyuanfan/Library/Python/3.9/lib/python/site-packages/rest_framework/views.py", line 509, in dispatch
    response = self.handle_exception(exc)
  File "/Users/hongyuanfan/Library/Python/3.9/lib/python/site-packages/rest_framework/views.py", line 469, in handle_exception
    self.raise_uncaught_exception(exc)
  File "/Users/hongyuanfan/Library/Python/3.9/lib/python/site-packages/rest_framework/views.py", line 480, in raise_uncaught_exception
    raise exc
  File "/Users/hongyuanfan/Library/Python/3.9/lib/python/site-packages/rest_framework/views.py", line 506, in dispatch
    response = handler(request, *args, **kwargs)
  File "/Users/hongyuanfan/Library/Python/3.9/lib/python/site-packages/rest_framework/mixins.py", line 43, in list
    return self.get_paginated_response(serializer.data)
  File "/Users/hongyuanfan/Library/Python/3.9/lib/python/site-packages/rest_framework/serializers.py", line 768, in data
    ret = super().data
  File "/Users/hongyuanfan/Library/Python/3.9/lib/python/site-packages/rest_framework/serializers.py", line 253, in data
    self._data = self.to_representation(self.instance)
  File "/Users/hongyuanfan/Library/Python/3.9/lib/python/site-packages/rest_framework/serializers.py", line 686, in to_representation
    return [
  File "/Users/hongyuanfan/Library/Python/3.9/lib/python/site-packages/rest_framework/serializers.py", line 687, in <listcomp>
    self.child.to_representation(item) for item in iterable
  File "/Users/hongyuanfan/Library/Python/3.9/lib/python/site-packages/rest_framework/serializers.py", line 507, in to_representation
    for field in fields:
  File "/Users/hongyuanfan/Library/Python/3.9/lib/python/site-packages/rest_framework/serializers.py", line 368, in _readable_fields
    for field in self.fields.values():
  File "/Users/hongyuanfan/Library/Python/3.9/lib/python/site-packages/django/utils/functional.py", line 57, in __get__
    res = instance.__dict__[self.name] = self.func(instance)
  File "/Users/hongyuanfan/Library/Python/3.9/lib/python/site-packages/rest_framework/serializers.py", line 356, in fields
    for key, value in self.get_fields().items():
  File "/Users/hongyuanfan/Library/Python/3.9/lib/python/site-packages/rest_framework/serializers.py", line 1076, in get_fields
    field_class, field_kwargs = self.build_field(
  File "/Users/hongyuanfan/Library/Python/3.9/lib/python/site-packages/rest_framework/serializers.py", line 1222, in build_field
    return self.build_unknown_field(field_name, model_class)
  File "/Users/hongyuanfan/Library/Python/3.9/lib/python/site-packages/rest_framework/serializers.py", line 1340, in build_unknown_field
    raise ImproperlyConfigured(
django.core.exceptions.ImproperlyConfigured: Field name `property` is not valid for model `Application`.
ERROR 2025-04-21 11:25:10,819 log Internal Server Error: /api/applications/applications/1/
Traceback (most recent call last):
  File "/Users/hongyuanfan/Library/Python/3.9/lib/python/site-packages/django/core/handlers/exception.py", line 55, in inner
    response = get_response(request)
  File "/Users/hongyuanfan/Library/Python/3.9/lib/python/site-packages/django/core/handlers/base.py", line 197, in _get_response
    response = wrapped_callback(request, *callback_args, **callback_kwargs)
  File "/Users/hongyuanfan/Library/Python/3.9/lib/python/site-packages/django/views/decorators/csrf.py", line 56, in wrapper_view
    return view_func(*args, **kwargs)
  File "/Users/hongyuanfan/Library/Python/3.9/lib/python/site-packages/rest_framework/viewsets.py", line 125, in view
    return self.dispatch(request, *args, **kwargs)
  File "/Users/hongyuanfan/Library/Python/3.9/lib/python/site-packages/rest_framework/views.py", line 509, in dispatch
    response = self.handle_exception(exc)
  File "/Users/hongyuanfan/Library/Python/3.9/lib/python/site-packages/rest_framework/views.py", line 469, in handle_exception
    self.raise_uncaught_exception(exc)
  File "/Users/hongyuanfan/Library/Python/3.9/lib/python/site-packages/rest_framework/views.py", line 480, in raise_uncaught_exception
    raise exc
  File "/Users/hongyuanfan/Library/Python/3.9/lib/python/site-packages/rest_framework/views.py", line 506, in dispatch
    response = handler(request, *args, **kwargs)
  File "/Users/hongyuanfan/Library/Python/3.9/lib/python/site-packages/rest_framework/mixins.py", line 82, in partial_update
    return self.update(request, *args, **kwargs)
  File "/Users/hongyuanfan/Library/Python/3.9/lib/python/site-packages/rest_framework/mixins.py", line 67, in update
    serializer.is_valid(raise_exception=True)
  File "/Users/hongyuanfan/Library/Python/3.9/lib/python/site-packages/rest_framework/serializers.py", line 227, in is_valid
    self._validated_data = self.run_validation(self.initial_data)
  File "/Users/hongyuanfan/Library/Python/3.9/lib/python/site-packages/rest_framework/serializers.py", line 426, in run_validation
    value = self.to_internal_value(data)
  File "/Users/hongyuanfan/Library/Python/3.9/lib/python/site-packages/rest_framework/serializers.py", line 479, in to_internal_value
    for field in fields:
  File "/Users/hongyuanfan/Library/Python/3.9/lib/python/site-packages/rest_framework/serializers.py", line 362, in _writable_fields
    for field in self.fields.values():
  File "/Users/hongyuanfan/Library/Python/3.9/lib/python/site-packages/django/utils/functional.py", line 57, in __get__
    res = instance.__dict__[self.name] = self.func(instance)
  File "/Users/hongyuanfan/Library/Python/3.9/lib/python/site-packages/rest_framework/serializers.py", line 356, in fields
    for key, value in self.get_fields().items():
  File "/Users/hongyuanfan/Library/Python/3.9/lib/python/site-packages/rest_framework/serializers.py", line 1076, in get_fields
    field_class, field_kwargs = self.build_field(
  File "/Users/hongyuanfan/Library/Python/3.9/lib/python/site-packages/rest_framework/serializers.py", line 1222, in build_field
    return self.build_unknown_field(field_name, model_class)
  File "/Users/hongyuanfan/Library/Python/3.9/lib/python/site-packages/rest_framework/serializers.py", line 1340, in build_unknown_field
    raise ImproperlyConfigured(
django.core.exceptions.ImproperlyConfigured: Field name `property` is not valid for model `Application`.
ERROR 2025-04-21 11:25:11,744 log Internal Server Error: /api/applications/applications/1/update_stage/
Traceback (most recent call last):
  File "/Users/hongyuanfan/Library/Python/3.9/lib/python/site-packages/django/core/handlers/exception.py", line 55, in inner
    response = get_response(request)
  File "/Users/hongyuanfan/Library/Python/3.9/lib/python/site-packages/django/core/handlers/base.py", line 197, in _get_response
    response = wrapped_callback(request, *callback_args, **callback_kwargs)
  File "/Users/hongyuanfan/Library/Python/3.9/lib/python/site-packages/django/views/decorators/csrf.py", line 56, in wrapper_view
    return view_func(*args, **kwargs)
  File "/Users/hongyuanfan/Library/Python/3.9/lib/python/site-packages/rest_framework/viewsets.py", line 125, in view
    return self.dispatch(request, *args, **kwargs)
  File "/Users/hongyuanfan/Library/Python/3.9/lib/python/site-packages/rest_framework/views.py", line 509, in dispatch
    response = self.handle_exception(exc)
  File "/Users/hongyuanfan/Library/Python/3.9/lib/python/site-packages/rest_framework/views.py", line 469, in handle_exception
    self.raise_uncaught_exception(exc)
  File "/Users/hongyuanfan/Library/Python/3.9/lib/python/site-packages/rest_framework/views.py", line 480, in raise_uncaught_exception
    raise exc
  File "/Users/hongyuanfan/Library/Python/3.9/lib/python/site-packages/rest_framework/views.py", line 506, in dispatch
    response = handler(request, *args, **kwargs)
  File "/Users/hongyuanfan/Desktop/LoanAPPV3/backenddjango/applications/views.py", line 80, in update_stage
    return Response(ApplicationDetailSerializer(application, context={'request': request}).data)
  File "/Users/hongyuanfan/Library/Python/3.9/lib/python/site-packages/rest_framework/serializers.py", line 555, in data
    ret = super().data
  File "/Users/hongyuanfan/Library/Python/3.9/lib/python/site-packages/rest_framework/serializers.py", line 253, in data
    self._data = self.to_representation(self.instance)
  File "/Users/hongyuanfan/Library/Python/3.9/lib/python/site-packages/rest_framework/serializers.py", line 507, in to_representation
    for field in fields:
  File "/Users/hongyuanfan/Library/Python/3.9/lib/python/site-packages/rest_framework/serializers.py", line 368, in _readable_fields
    for field in self.fields.values():
  File "/Users/hongyuanfan/Library/Python/3.9/lib/python/site-packages/django/utils/functional.py", line 57, in __get__
    res = instance.__dict__[self.name] = self.func(instance)
  File "/Users/hongyuanfan/Library/Python/3.9/lib/python/site-packages/rest_framework/serializers.py", line 356, in fields
    for key, value in self.get_fields().items():
  File "/Users/hongyuanfan/Library/Python/3.9/lib/python/site-packages/rest_framework/serializers.py", line 1076, in get_fields
    field_class, field_kwargs = self.build_field(
  File "/Users/hongyuanfan/Library/Python/3.9/lib/python/site-packages/rest_framework/serializers.py", line 1222, in build_field
    return self.build_unknown_field(field_name, model_class)
  File "/Users/hongyuanfan/Library/Python/3.9/lib/python/site-packages/rest_framework/serializers.py", line 1340, in build_unknown_field
    raise ImproperlyConfigured(
django.core.exceptions.ImproperlyConfigured: Field name `property` is not valid for model `Application`.
INFO 2025-04-21 11:25:12,260 views Login attempt for email: admin@example.com
WARNING 2025-04-21 11:25:12,428 log Unauthorized: /api/users/auth/login/
INFO 2025-04-21 11:25:12,923 views Login attempt for email: admin@example.com
INFO 2025-04-21 11:25:15,571 views Registration attempt with data: {'email': 'admin@example.com', 'password': 'newpassword123', 'first_name': 'Duplicate', 'last_name': 'User', 'role': 'client'}
ERROR 2025-04-21 11:25:15,573 views Registration validation errors: {'email': [ErrorDetail(string='user with this email address already exists.', code='unique')]}
WARNING 2025-04-21 11:25:15,573 log Bad Request: /api/users/auth/register/
INFO 2025-04-21 11:25:16,071 views Registration attempt with data: {'email': 'newuser@example.com', 'password': 'newpassword123', 'first_name': 'New', 'last_name': 'User', 'role': 'client'}
WARNING 2025-04-21 11:25:17,241 log Forbidden: /api/users/users/
WARNING 2025-04-21 11:28:11,212 log Not Found: /api/applications/applications/99999/
WARNING 2025-04-21 11:28:11,213 log Bad Request: /api/applications/applications/
WARNING 2025-04-21 11:28:11,215 log Bad Request: /api/applications/applications/1/
WARNING 2025-04-21 11:28:11,217 log Unauthorized: /api/applications/applications/
ERROR 2025-04-21 11:28:11,222 log Internal Server Error: /api/applications/applications/
Traceback (most recent call last):
  File "/Users/hongyuanfan/Library/Python/3.9/lib/python/site-packages/django/core/handlers/exception.py", line 55, in inner
    response = get_response(request)
  File "/Users/hongyuanfan/Library/Python/3.9/lib/python/site-packages/django/core/handlers/base.py", line 197, in _get_response
    response = wrapped_callback(request, *callback_args, **callback_kwargs)
  File "/Users/hongyuanfan/Library/Python/3.9/lib/python/site-packages/django/views/decorators/csrf.py", line 56, in wrapper_view
    return view_func(*args, **kwargs)
  File "/Users/hongyuanfan/Library/Python/3.9/lib/python/site-packages/rest_framework/viewsets.py", line 125, in view
    return self.dispatch(request, *args, **kwargs)
  File "/Users/hongyuanfan/Library/Python/3.9/lib/python/site-packages/rest_framework/views.py", line 509, in dispatch
    response = self.handle_exception(exc)
  File "/Users/hongyuanfan/Library/Python/3.9/lib/python/site-packages/rest_framework/views.py", line 469, in handle_exception
    self.raise_uncaught_exception(exc)
  File "/Users/hongyuanfan/Library/Python/3.9/lib/python/site-packages/rest_framework/views.py", line 480, in raise_uncaught_exception
    raise exc
  File "/Users/hongyuanfan/Library/Python/3.9/lib/python/site-packages/rest_framework/views.py", line 506, in dispatch
    response = handler(request, *args, **kwargs)
  File "/Users/hongyuanfan/Library/Python/3.9/lib/python/site-packages/rest_framework/mixins.py", line 19, in create
    self.perform_create(serializer)
  File "/Users/hongyuanfan/Desktop/LoanAPPV3/backenddjango/applications/views.py", line 64, in perform_create
    serializer.save(created_by=self.request.user)
  File "/Users/hongyuanfan/Library/Python/3.9/lib/python/site-packages/rest_framework/serializers.py", line 212, in save
    self.instance = self.create(validated_data)
  File "/Users/hongyuanfan/Desktop/LoanAPPV3/backenddjango/applications/serializers.py", line 183, in create
    Notification.objects.create(
  File "/Users/hongyuanfan/Library/Python/3.9/lib/python/site-packages/django/db/models/manager.py", line 87, in manager_method
    return getattr(self.get_queryset(), name)(*args, **kwargs)
  File "/Users/hongyuanfan/Library/Python/3.9/lib/python/site-packages/django/db/models/query.py", line 656, in create
    obj = self.model(**kwargs)
  File "/Users/hongyuanfan/Library/Python/3.9/lib/python/site-packages/django/db/models/base.py", line 567, in __init__
    raise TypeError(
TypeError: Notification() got unexpected keyword arguments: 'related_id'
ERROR 2025-04-21 11:28:11,901 log Internal Server Error: /api/applications/applications/
Traceback (most recent call last):
  File "/Users/hongyuanfan/Library/Python/3.9/lib/python/site-packages/django/core/handlers/exception.py", line 55, in inner
    response = get_response(request)
  File "/Users/hongyuanfan/Library/Python/3.9/lib/python/site-packages/django/core/handlers/base.py", line 197, in _get_response
    response = wrapped_callback(request, *callback_args, **callback_kwargs)
  File "/Users/hongyuanfan/Library/Python/3.9/lib/python/site-packages/django/views/decorators/csrf.py", line 56, in wrapper_view
    return view_func(*args, **kwargs)
  File "/Users/hongyuanfan/Library/Python/3.9/lib/python/site-packages/rest_framework/viewsets.py", line 125, in view
    return self.dispatch(request, *args, **kwargs)
  File "/Users/hongyuanfan/Library/Python/3.9/lib/python/site-packages/rest_framework/views.py", line 509, in dispatch
    response = self.handle_exception(exc)
  File "/Users/hongyuanfan/Library/Python/3.9/lib/python/site-packages/rest_framework/views.py", line 469, in handle_exception
    self.raise_uncaught_exception(exc)
  File "/Users/hongyuanfan/Library/Python/3.9/lib/python/site-packages/rest_framework/views.py", line 480, in raise_uncaught_exception
    raise exc
  File "/Users/hongyuanfan/Library/Python/3.9/lib/python/site-packages/rest_framework/views.py", line 506, in dispatch
    response = handler(request, *args, **kwargs)
  File "/Users/hongyuanfan/Library/Python/3.9/lib/python/site-packages/rest_framework/mixins.py", line 43, in list
    return self.get_paginated_response(serializer.data)
  File "/Users/hongyuanfan/Library/Python/3.9/lib/python/site-packages/rest_framework/serializers.py", line 768, in data
    ret = super().data
  File "/Users/hongyuanfan/Library/Python/3.9/lib/python/site-packages/rest_framework/serializers.py", line 253, in data
    self._data = self.to_representation(self.instance)
  File "/Users/hongyuanfan/Library/Python/3.9/lib/python/site-packages/rest_framework/serializers.py", line 686, in to_representation
    return [
  File "/Users/hongyuanfan/Library/Python/3.9/lib/python/site-packages/rest_framework/serializers.py", line 687, in <listcomp>
    self.child.to_representation(item) for item in iterable
  File "/Users/hongyuanfan/Library/Python/3.9/lib/python/site-packages/rest_framework/serializers.py", line 522, in to_representation
    ret[field.field_name] = field.to_representation(attribute)
  File "/Users/hongyuanfan/Library/Python/3.9/lib/python/site-packages/rest_framework/serializers.py", line 686, in to_representation
    return [
  File "/Users/hongyuanfan/Library/Python/3.9/lib/python/site-packages/rest_framework/serializers.py", line 687, in <listcomp>
    self.child.to_representation(item) for item in iterable
  File "/Users/hongyuanfan/Library/Python/3.9/lib/python/site-packages/rest_framework/serializers.py", line 507, in to_representation
    for field in fields:
  File "/Users/hongyuanfan/Library/Python/3.9/lib/python/site-packages/rest_framework/serializers.py", line 368, in _readable_fields
    for field in self.fields.values():
  File "/Users/hongyuanfan/Library/Python/3.9/lib/python/site-packages/django/utils/functional.py", line 57, in __get__
    res = instance.__dict__[self.name] = self.func(instance)
  File "/Users/hongyuanfan/Library/Python/3.9/lib/python/site-packages/rest_framework/serializers.py", line 356, in fields
    for key, value in self.get_fields().items():
  File "/Users/hongyuanfan/Library/Python/3.9/lib/python/site-packages/rest_framework/serializers.py", line 1076, in get_fields
    field_class, field_kwargs = self.build_field(
  File "/Users/hongyuanfan/Library/Python/3.9/lib/python/site-packages/rest_framework/serializers.py", line 1222, in build_field
    return self.build_unknown_field(field_name, model_class)
  File "/Users/hongyuanfan/Library/Python/3.9/lib/python/site-packages/rest_framework/serializers.py", line 1340, in build_unknown_field
    raise ImproperlyConfigured(
django.core.exceptions.ImproperlyConfigured: Field name `dob` is not valid for model `Borrower`.
INFO 2025-04-21 11:28:13,214 views Login attempt for email: admin@example.com
ERROR 2025-04-21 11:28:13,421 log Internal Server Error: /api/applications/applications/
Traceback (most recent call last):
  File "/Users/hongyuanfan/Library/Python/3.9/lib/python/site-packages/django/core/handlers/exception.py", line 55, in inner
    response = get_response(request)
  File "/Users/hongyuanfan/Library/Python/3.9/lib/python/site-packages/django/core/handlers/base.py", line 197, in _get_response
    response = wrapped_callback(request, *callback_args, **callback_kwargs)
  File "/Users/hongyuanfan/Library/Python/3.9/lib/python/site-packages/django/views/decorators/csrf.py", line 56, in wrapper_view
    return view_func(*args, **kwargs)
  File "/Users/hongyuanfan/Library/Python/3.9/lib/python/site-packages/rest_framework/viewsets.py", line 125, in view
    return self.dispatch(request, *args, **kwargs)
  File "/Users/hongyuanfan/Library/Python/3.9/lib/python/site-packages/rest_framework/views.py", line 509, in dispatch
    response = self.handle_exception(exc)
  File "/Users/hongyuanfan/Library/Python/3.9/lib/python/site-packages/rest_framework/views.py", line 469, in handle_exception
    self.raise_uncaught_exception(exc)
  File "/Users/hongyuanfan/Library/Python/3.9/lib/python/site-packages/rest_framework/views.py", line 480, in raise_uncaught_exception
    raise exc
  File "/Users/hongyuanfan/Library/Python/3.9/lib/python/site-packages/rest_framework/views.py", line 506, in dispatch
    response = handler(request, *args, **kwargs)
  File "/Users/hongyuanfan/Library/Python/3.9/lib/python/site-packages/rest_framework/mixins.py", line 43, in list
    return self.get_paginated_response(serializer.data)
  File "/Users/hongyuanfan/Library/Python/3.9/lib/python/site-packages/rest_framework/serializers.py", line 768, in data
    ret = super().data
  File "/Users/hongyuanfan/Library/Python/3.9/lib/python/site-packages/rest_framework/serializers.py", line 253, in data
    self._data = self.to_representation(self.instance)
  File "/Users/hongyuanfan/Library/Python/3.9/lib/python/site-packages/rest_framework/serializers.py", line 686, in to_representation
    return [
  File "/Users/hongyuanfan/Library/Python/3.9/lib/python/site-packages/rest_framework/serializers.py", line 687, in <listcomp>
    self.child.to_representation(item) for item in iterable
  File "/Users/hongyuanfan/Library/Python/3.9/lib/python/site-packages/rest_framework/serializers.py", line 522, in to_representation
    ret[field.field_name] = field.to_representation(attribute)
  File "/Users/hongyuanfan/Library/Python/3.9/lib/python/site-packages/rest_framework/serializers.py", line 686, in to_representation
    return [
  File "/Users/hongyuanfan/Library/Python/3.9/lib/python/site-packages/rest_framework/serializers.py", line 687, in <listcomp>
    self.child.to_representation(item) for item in iterable
  File "/Users/hongyuanfan/Library/Python/3.9/lib/python/site-packages/rest_framework/serializers.py", line 507, in to_representation
    for field in fields:
  File "/Users/hongyuanfan/Library/Python/3.9/lib/python/site-packages/rest_framework/serializers.py", line 368, in _readable_fields
    for field in self.fields.values():
  File "/Users/hongyuanfan/Library/Python/3.9/lib/python/site-packages/django/utils/functional.py", line 57, in __get__
    res = instance.__dict__[self.name] = self.func(instance)
  File "/Users/hongyuanfan/Library/Python/3.9/lib/python/site-packages/rest_framework/serializers.py", line 356, in fields
    for key, value in self.get_fields().items():
  File "/Users/hongyuanfan/Library/Python/3.9/lib/python/site-packages/rest_framework/serializers.py", line 1076, in get_fields
    field_class, field_kwargs = self.build_field(
  File "/Users/hongyuanfan/Library/Python/3.9/lib/python/site-packages/rest_framework/serializers.py", line 1222, in build_field
    return self.build_unknown_field(field_name, model_class)
  File "/Users/hongyuanfan/Library/Python/3.9/lib/python/site-packages/rest_framework/serializers.py", line 1340, in build_unknown_field
    raise ImproperlyConfigured(
django.core.exceptions.ImproperlyConfigured: Field name `dob` is not valid for model `Borrower`.
ERROR 2025-04-21 11:28:14,080 log Internal Server Error: /api/applications/applications/
Traceback (most recent call last):
  File "/Users/hongyuanfan/Library/Python/3.9/lib/python/site-packages/django/core/handlers/exception.py", line 55, in inner
    response = get_response(request)
  File "/Users/hongyuanfan/Library/Python/3.9/lib/python/site-packages/django/core/handlers/base.py", line 197, in _get_response
    response = wrapped_callback(request, *callback_args, **callback_kwargs)
  File "/Users/hongyuanfan/Library/Python/3.9/lib/python/site-packages/django/views/decorators/csrf.py", line 56, in wrapper_view
    return view_func(*args, **kwargs)
  File "/Users/hongyuanfan/Library/Python/3.9/lib/python/site-packages/rest_framework/viewsets.py", line 125, in view
    return self.dispatch(request, *args, **kwargs)
  File "/Users/hongyuanfan/Library/Python/3.9/lib/python/site-packages/rest_framework/views.py", line 509, in dispatch
    response = self.handle_exception(exc)
  File "/Users/hongyuanfan/Library/Python/3.9/lib/python/site-packages/rest_framework/views.py", line 469, in handle_exception
    self.raise_uncaught_exception(exc)
  File "/Users/hongyuanfan/Library/Python/3.9/lib/python/site-packages/rest_framework/views.py", line 480, in raise_uncaught_exception
    raise exc
  File "/Users/hongyuanfan/Library/Python/3.9/lib/python/site-packages/rest_framework/views.py", line 506, in dispatch
    response = handler(request, *args, **kwargs)
  File "/Users/hongyuanfan/Library/Python/3.9/lib/python/site-packages/rest_framework/mixins.py", line 18, in create
    serializer.is_valid(raise_exception=True)
  File "/Users/hongyuanfan/Library/Python/3.9/lib/python/site-packages/rest_framework/serializers.py", line 227, in is_valid
    self._validated_data = self.run_validation(self.initial_data)
  File "/Users/hongyuanfan/Library/Python/3.9/lib/python/site-packages/rest_framework/serializers.py", line 426, in run_validation
    value = self.to_internal_value(data)
  File "/Users/hongyuanfan/Library/Python/3.9/lib/python/site-packages/rest_framework/serializers.py", line 483, in to_internal_value
    validated_value = field.run_validation(primitive_value)
  File "/Users/hongyuanfan/Library/Python/3.9/lib/python/site-packages/rest_framework/serializers.py", line 618, in run_validation
    value = self.to_internal_value(data)
  File "/Users/hongyuanfan/Library/Python/3.9/lib/python/site-packages/rest_framework/serializers.py", line 666, in to_internal_value
    validated = self.child.run_validation(item)
  File "/Users/hongyuanfan/Library/Python/3.9/lib/python/site-packages/rest_framework/serializers.py", line 426, in run_validation
    value = self.to_internal_value(data)
  File "/Users/hongyuanfan/Library/Python/3.9/lib/python/site-packages/rest_framework/serializers.py", line 479, in to_internal_value
    for field in fields:
  File "/Users/hongyuanfan/Library/Python/3.9/lib/python/site-packages/rest_framework/serializers.py", line 362, in _writable_fields
    for field in self.fields.values():
  File "/Users/hongyuanfan/Library/Python/3.9/lib/python/site-packages/django/utils/functional.py", line 57, in __get__
    res = instance.__dict__[self.name] = self.func(instance)
  File "/Users/hongyuanfan/Library/Python/3.9/lib/python/site-packages/rest_framework/serializers.py", line 356, in fields
    for key, value in self.get_fields().items():
  File "/Users/hongyuanfan/Library/Python/3.9/lib/python/site-packages/rest_framework/serializers.py", line 1076, in get_fields
    field_class, field_kwargs = self.build_field(
  File "/Users/hongyuanfan/Library/Python/3.9/lib/python/site-packages/rest_framework/serializers.py", line 1222, in build_field
    return self.build_unknown_field(field_name, model_class)
  File "/Users/hongyuanfan/Library/Python/3.9/lib/python/site-packages/rest_framework/serializers.py", line 1340, in build_unknown_field
    raise ImproperlyConfigured(
django.core.exceptions.ImproperlyConfigured: Field name `dob` is not valid for model `Borrower`.
ERROR 2025-04-21 11:28:14,743 log Internal Server Error: /api/applications/applications/
Traceback (most recent call last):
  File "/Users/hongyuanfan/Library/Python/3.9/lib/python/site-packages/django/core/handlers/exception.py", line 55, in inner
    response = get_response(request)
  File "/Users/hongyuanfan/Library/Python/3.9/lib/python/site-packages/django/core/handlers/base.py", line 197, in _get_response
    response = wrapped_callback(request, *callback_args, **callback_kwargs)
  File "/Users/hongyuanfan/Library/Python/3.9/lib/python/site-packages/django/views/decorators/csrf.py", line 56, in wrapper_view
    return view_func(*args, **kwargs)
  File "/Users/hongyuanfan/Library/Python/3.9/lib/python/site-packages/rest_framework/viewsets.py", line 125, in view
    return self.dispatch(request, *args, **kwargs)
  File "/Users/hongyuanfan/Library/Python/3.9/lib/python/site-packages/rest_framework/views.py", line 509, in dispatch
    response = self.handle_exception(exc)
  File "/Users/hongyuanfan/Library/Python/3.9/lib/python/site-packages/rest_framework/views.py", line 469, in handle_exception
    self.raise_uncaught_exception(exc)
  File "/Users/hongyuanfan/Library/Python/3.9/lib/python/site-packages/rest_framework/views.py", line 480, in raise_uncaught_exception
    raise exc
  File "/Users/hongyuanfan/Library/Python/3.9/lib/python/site-packages/rest_framework/views.py", line 506, in dispatch
    response = handler(request, *args, **kwargs)
  File "/Users/hongyuanfan/Library/Python/3.9/lib/python/site-packages/rest_framework/mixins.py", line 18, in create
    serializer.is_valid(raise_exception=True)
  File "/Users/hongyuanfan/Library/Python/3.9/lib/python/site-packages/rest_framework/serializers.py", line 227, in is_valid
    self._validated_data = self.run_validation(self.initial_data)
  File "/Users/hongyuanfan/Library/Python/3.9/lib/python/site-packages/rest_framework/serializers.py", line 426, in run_validation
    value = self.to_internal_value(data)
  File "/Users/hongyuanfan/Library/Python/3.9/lib/python/site-packages/rest_framework/serializers.py", line 483, in to_internal_value
    validated_value = field.run_validation(primitive_value)
  File "/Users/hongyuanfan/Library/Python/3.9/lib/python/site-packages/rest_framework/serializers.py", line 618, in run_validation
    value = self.to_internal_value(data)
  File "/Users/hongyuanfan/Library/Python/3.9/lib/python/site-packages/rest_framework/serializers.py", line 666, in to_internal_value
    validated = self.child.run_validation(item)
  File "/Users/hongyuanfan/Library/Python/3.9/lib/python/site-packages/rest_framework/serializers.py", line 426, in run_validation
    value = self.to_internal_value(data)
  File "/Users/hongyuanfan/Library/Python/3.9/lib/python/site-packages/rest_framework/serializers.py", line 479, in to_internal_value
    for field in fields:
  File "/Users/hongyuanfan/Library/Python/3.9/lib/python/site-packages/rest_framework/serializers.py", line 362, in _writable_fields
    for field in self.fields.values():
  File "/Users/hongyuanfan/Library/Python/3.9/lib/python/site-packages/django/utils/functional.py", line 57, in __get__
    res = instance.__dict__[self.name] = self.func(instance)
  File "/Users/hongyuanfan/Library/Python/3.9/lib/python/site-packages/rest_framework/serializers.py", line 356, in fields
    for key, value in self.get_fields().items():
  File "/Users/hongyuanfan/Library/Python/3.9/lib/python/site-packages/rest_framework/serializers.py", line 1076, in get_fields
    field_class, field_kwargs = self.build_field(
  File "/Users/hongyuanfan/Library/Python/3.9/lib/python/site-packages/rest_framework/serializers.py", line 1222, in build_field
    return self.build_unknown_field(field_name, model_class)
  File "/Users/hongyuanfan/Library/Python/3.9/lib/python/site-packages/rest_framework/serializers.py", line 1340, in build_unknown_field
    raise ImproperlyConfigured(
django.core.exceptions.ImproperlyConfigured: Field name `dob` is not valid for model `Borrower`.
ERROR 2025-04-21 11:28:15,407 log Internal Server Error: /api/applications/applications/
Traceback (most recent call last):
  File "/Users/hongyuanfan/Library/Python/3.9/lib/python/site-packages/django/core/handlers/exception.py", line 55, in inner
    response = get_response(request)
  File "/Users/hongyuanfan/Library/Python/3.9/lib/python/site-packages/django/core/handlers/base.py", line 197, in _get_response
    response = wrapped_callback(request, *callback_args, **callback_kwargs)
  File "/Users/hongyuanfan/Library/Python/3.9/lib/python/site-packages/django/views/decorators/csrf.py", line 56, in wrapper_view
    return view_func(*args, **kwargs)
  File "/Users/hongyuanfan/Library/Python/3.9/lib/python/site-packages/rest_framework/viewsets.py", line 125, in view
    return self.dispatch(request, *args, **kwargs)
  File "/Users/hongyuanfan/Library/Python/3.9/lib/python/site-packages/rest_framework/views.py", line 509, in dispatch
    response = self.handle_exception(exc)
  File "/Users/hongyuanfan/Library/Python/3.9/lib/python/site-packages/rest_framework/views.py", line 469, in handle_exception
    self.raise_uncaught_exception(exc)
  File "/Users/hongyuanfan/Library/Python/3.9/lib/python/site-packages/rest_framework/views.py", line 480, in raise_uncaught_exception
    raise exc
  File "/Users/hongyuanfan/Library/Python/3.9/lib/python/site-packages/rest_framework/views.py", line 506, in dispatch
    response = handler(request, *args, **kwargs)
  File "/Users/hongyuanfan/Library/Python/3.9/lib/python/site-packages/rest_framework/mixins.py", line 43, in list
    return self.get_paginated_response(serializer.data)
  File "/Users/hongyuanfan/Library/Python/3.9/lib/python/site-packages/rest_framework/serializers.py", line 768, in data
    ret = super().data
  File "/Users/hongyuanfan/Library/Python/3.9/lib/python/site-packages/rest_framework/serializers.py", line 253, in data
    self._data = self.to_representation(self.instance)
  File "/Users/hongyuanfan/Library/Python/3.9/lib/python/site-packages/rest_framework/serializers.py", line 686, in to_representation
    return [
  File "/Users/hongyuanfan/Library/Python/3.9/lib/python/site-packages/rest_framework/serializers.py", line 687, in <listcomp>
    self.child.to_representation(item) for item in iterable
  File "/Users/hongyuanfan/Library/Python/3.9/lib/python/site-packages/rest_framework/serializers.py", line 522, in to_representation
    ret[field.field_name] = field.to_representation(attribute)
  File "/Users/hongyuanfan/Library/Python/3.9/lib/python/site-packages/rest_framework/serializers.py", line 686, in to_representation
    return [
  File "/Users/hongyuanfan/Library/Python/3.9/lib/python/site-packages/rest_framework/serializers.py", line 687, in <listcomp>
    self.child.to_representation(item) for item in iterable
  File "/Users/hongyuanfan/Library/Python/3.9/lib/python/site-packages/rest_framework/serializers.py", line 507, in to_representation
    for field in fields:
  File "/Users/hongyuanfan/Library/Python/3.9/lib/python/site-packages/rest_framework/serializers.py", line 368, in _readable_fields
    for field in self.fields.values():
  File "/Users/hongyuanfan/Library/Python/3.9/lib/python/site-packages/django/utils/functional.py", line 57, in __get__
    res = instance.__dict__[self.name] = self.func(instance)
  File "/Users/hongyuanfan/Library/Python/3.9/lib/python/site-packages/rest_framework/serializers.py", line 356, in fields
    for key, value in self.get_fields().items():
  File "/Users/hongyuanfan/Library/Python/3.9/lib/python/site-packages/rest_framework/serializers.py", line 1076, in get_fields
    field_class, field_kwargs = self.build_field(
  File "/Users/hongyuanfan/Library/Python/3.9/lib/python/site-packages/rest_framework/serializers.py", line 1222, in build_field
    return self.build_unknown_field(field_name, model_class)
  File "/Users/hongyuanfan/Library/Python/3.9/lib/python/site-packages/rest_framework/serializers.py", line 1340, in build_unknown_field
    raise ImproperlyConfigured(
django.core.exceptions.ImproperlyConfigured: Field name `dob` is not valid for model `Borrower`.
WARNING 2025-04-21 11:28:16,766 log Bad Request: /api/applications/applications/1/add_fee/
WARNING 2025-04-21 11:28:18,098 log Bad Request: /api/applications/applications/1/add_repayment/
ERROR 2025-04-21 11:28:18,760 log Internal Server Error: /api/applications/applications/1/
Traceback (most recent call last):
  File "/Users/hongyuanfan/Library/Python/3.9/lib/python/site-packages/django/core/handlers/exception.py", line 55, in inner
    response = get_response(request)
  File "/Users/hongyuanfan/Library/Python/3.9/lib/python/site-packages/django/core/handlers/base.py", line 197, in _get_response
    response = wrapped_callback(request, *callback_args, **callback_kwargs)
  File "/Users/hongyuanfan/Library/Python/3.9/lib/python/site-packages/django/views/decorators/csrf.py", line 56, in wrapper_view
    return view_func(*args, **kwargs)
  File "/Users/hongyuanfan/Library/Python/3.9/lib/python/site-packages/rest_framework/viewsets.py", line 125, in view
    return self.dispatch(request, *args, **kwargs)
  File "/Users/hongyuanfan/Library/Python/3.9/lib/python/site-packages/rest_framework/views.py", line 509, in dispatch
    response = self.handle_exception(exc)
  File "/Users/hongyuanfan/Library/Python/3.9/lib/python/site-packages/rest_framework/views.py", line 469, in handle_exception
    self.raise_uncaught_exception(exc)
  File "/Users/hongyuanfan/Library/Python/3.9/lib/python/site-packages/rest_framework/views.py", line 480, in raise_uncaught_exception
    raise exc
  File "/Users/hongyuanfan/Library/Python/3.9/lib/python/site-packages/rest_framework/views.py", line 506, in dispatch
    response = handler(request, *args, **kwargs)
  File "/Users/hongyuanfan/Library/Python/3.9/lib/python/site-packages/rest_framework/mixins.py", line 56, in retrieve
    return Response(serializer.data)
  File "/Users/hongyuanfan/Library/Python/3.9/lib/python/site-packages/rest_framework/serializers.py", line 555, in data
    ret = super().data
  File "/Users/hongyuanfan/Library/Python/3.9/lib/python/site-packages/rest_framework/serializers.py", line 253, in data
    self._data = self.to_representation(self.instance)
  File "/Users/hongyuanfan/Library/Python/3.9/lib/python/site-packages/rest_framework/serializers.py", line 522, in to_representation
    ret[field.field_name] = field.to_representation(attribute)
  File "/Users/hongyuanfan/Library/Python/3.9/lib/python/site-packages/rest_framework/serializers.py", line 686, in to_representation
    return [
  File "/Users/hongyuanfan/Library/Python/3.9/lib/python/site-packages/rest_framework/serializers.py", line 687, in <listcomp>
    self.child.to_representation(item) for item in iterable
  File "/Users/hongyuanfan/Library/Python/3.9/lib/python/site-packages/rest_framework/serializers.py", line 507, in to_representation
    for field in fields:
  File "/Users/hongyuanfan/Library/Python/3.9/lib/python/site-packages/rest_framework/serializers.py", line 368, in _readable_fields
    for field in self.fields.values():
  File "/Users/hongyuanfan/Library/Python/3.9/lib/python/site-packages/django/utils/functional.py", line 57, in __get__
    res = instance.__dict__[self.name] = self.func(instance)
  File "/Users/hongyuanfan/Library/Python/3.9/lib/python/site-packages/rest_framework/serializers.py", line 356, in fields
    for key, value in self.get_fields().items():
  File "/Users/hongyuanfan/Library/Python/3.9/lib/python/site-packages/rest_framework/serializers.py", line 1076, in get_fields
    field_class, field_kwargs = self.build_field(
  File "/Users/hongyuanfan/Library/Python/3.9/lib/python/site-packages/rest_framework/serializers.py", line 1222, in build_field
    return self.build_unknown_field(field_name, model_class)
  File "/Users/hongyuanfan/Library/Python/3.9/lib/python/site-packages/rest_framework/serializers.py", line 1340, in build_unknown_field
    raise ImproperlyConfigured(
django.core.exceptions.ImproperlyConfigured: Field name `dob` is not valid for model `Borrower`.
ERROR 2025-04-21 11:28:19,434 log Internal Server Error: /api/applications/applications/
Traceback (most recent call last):
  File "/Users/hongyuanfan/Library/Python/3.9/lib/python/site-packages/django/core/handlers/exception.py", line 55, in inner
    response = get_response(request)
  File "/Users/hongyuanfan/Library/Python/3.9/lib/python/site-packages/django/core/handlers/base.py", line 197, in _get_response
    response = wrapped_callback(request, *callback_args, **callback_kwargs)
  File "/Users/hongyuanfan/Library/Python/3.9/lib/python/site-packages/django/views/decorators/csrf.py", line 56, in wrapper_view
    return view_func(*args, **kwargs)
  File "/Users/hongyuanfan/Library/Python/3.9/lib/python/site-packages/rest_framework/viewsets.py", line 125, in view
    return self.dispatch(request, *args, **kwargs)
  File "/Users/hongyuanfan/Library/Python/3.9/lib/python/site-packages/rest_framework/views.py", line 509, in dispatch
    response = self.handle_exception(exc)
  File "/Users/hongyuanfan/Library/Python/3.9/lib/python/site-packages/rest_framework/views.py", line 469, in handle_exception
    self.raise_uncaught_exception(exc)
  File "/Users/hongyuanfan/Library/Python/3.9/lib/python/site-packages/rest_framework/views.py", line 480, in raise_uncaught_exception
    raise exc
  File "/Users/hongyuanfan/Library/Python/3.9/lib/python/site-packages/rest_framework/views.py", line 506, in dispatch
    response = handler(request, *args, **kwargs)
  File "/Users/hongyuanfan/Library/Python/3.9/lib/python/site-packages/rest_framework/mixins.py", line 43, in list
    return self.get_paginated_response(serializer.data)
  File "/Users/hongyuanfan/Library/Python/3.9/lib/python/site-packages/rest_framework/serializers.py", line 768, in data
    ret = super().data
  File "/Users/hongyuanfan/Library/Python/3.9/lib/python/site-packages/rest_framework/serializers.py", line 253, in data
    self._data = self.to_representation(self.instance)
  File "/Users/hongyuanfan/Library/Python/3.9/lib/python/site-packages/rest_framework/serializers.py", line 686, in to_representation
    return [
  File "/Users/hongyuanfan/Library/Python/3.9/lib/python/site-packages/rest_framework/serializers.py", line 687, in <listcomp>
    self.child.to_representation(item) for item in iterable
  File "/Users/hongyuanfan/Library/Python/3.9/lib/python/site-packages/rest_framework/serializers.py", line 522, in to_representation
    ret[field.field_name] = field.to_representation(attribute)
  File "/Users/hongyuanfan/Library/Python/3.9/lib/python/site-packages/rest_framework/serializers.py", line 686, in to_representation
    return [
  File "/Users/hongyuanfan/Library/Python/3.9/lib/python/site-packages/rest_framework/serializers.py", line 687, in <listcomp>
    self.child.to_representation(item) for item in iterable
  File "/Users/hongyuanfan/Library/Python/3.9/lib/python/site-packages/rest_framework/serializers.py", line 507, in to_representation
    for field in fields:
  File "/Users/hongyuanfan/Library/Python/3.9/lib/python/site-packages/rest_framework/serializers.py", line 368, in _readable_fields
    for field in self.fields.values():
  File "/Users/hongyuanfan/Library/Python/3.9/lib/python/site-packages/django/utils/functional.py", line 57, in __get__
    res = instance.__dict__[self.name] = self.func(instance)
  File "/Users/hongyuanfan/Library/Python/3.9/lib/python/site-packages/rest_framework/serializers.py", line 356, in fields
    for key, value in self.get_fields().items():
  File "/Users/hongyuanfan/Library/Python/3.9/lib/python/site-packages/rest_framework/serializers.py", line 1076, in get_fields
    field_class, field_kwargs = self.build_field(
  File "/Users/hongyuanfan/Library/Python/3.9/lib/python/site-packages/rest_framework/serializers.py", line 1222, in build_field
    return self.build_unknown_field(field_name, model_class)
  File "/Users/hongyuanfan/Library/Python/3.9/lib/python/site-packages/rest_framework/serializers.py", line 1340, in build_unknown_field
    raise ImproperlyConfigured(
django.core.exceptions.ImproperlyConfigured: Field name `dob` is not valid for model `Borrower`.
ERROR 2025-04-21 11:28:20,099 log Internal Server Error: /api/applications/applications/
Traceback (most recent call last):
  File "/Users/hongyuanfan/Library/Python/3.9/lib/python/site-packages/django/core/handlers/exception.py", line 55, in inner
    response = get_response(request)
  File "/Users/hongyuanfan/Library/Python/3.9/lib/python/site-packages/django/core/handlers/base.py", line 197, in _get_response
    response = wrapped_callback(request, *callback_args, **callback_kwargs)
  File "/Users/hongyuanfan/Library/Python/3.9/lib/python/site-packages/django/views/decorators/csrf.py", line 56, in wrapper_view
    return view_func(*args, **kwargs)
  File "/Users/hongyuanfan/Library/Python/3.9/lib/python/site-packages/rest_framework/viewsets.py", line 125, in view
    return self.dispatch(request, *args, **kwargs)
  File "/Users/hongyuanfan/Library/Python/3.9/lib/python/site-packages/rest_framework/views.py", line 509, in dispatch
    response = self.handle_exception(exc)
  File "/Users/hongyuanfan/Library/Python/3.9/lib/python/site-packages/rest_framework/views.py", line 469, in handle_exception
    self.raise_uncaught_exception(exc)
  File "/Users/hongyuanfan/Library/Python/3.9/lib/python/site-packages/rest_framework/views.py", line 480, in raise_uncaught_exception
    raise exc
  File "/Users/hongyuanfan/Library/Python/3.9/lib/python/site-packages/rest_framework/views.py", line 506, in dispatch
    response = handler(request, *args, **kwargs)
  File "/Users/hongyuanfan/Library/Python/3.9/lib/python/site-packages/rest_framework/mixins.py", line 18, in create
    serializer.is_valid(raise_exception=True)
  File "/Users/hongyuanfan/Library/Python/3.9/lib/python/site-packages/rest_framework/serializers.py", line 227, in is_valid
    self._validated_data = self.run_validation(self.initial_data)
  File "/Users/hongyuanfan/Library/Python/3.9/lib/python/site-packages/rest_framework/serializers.py", line 426, in run_validation
    value = self.to_internal_value(data)
  File "/Users/hongyuanfan/Library/Python/3.9/lib/python/site-packages/rest_framework/serializers.py", line 483, in to_internal_value
    validated_value = field.run_validation(primitive_value)
  File "/Users/hongyuanfan/Library/Python/3.9/lib/python/site-packages/rest_framework/serializers.py", line 618, in run_validation
    value = self.to_internal_value(data)
  File "/Users/hongyuanfan/Library/Python/3.9/lib/python/site-packages/rest_framework/serializers.py", line 666, in to_internal_value
    validated = self.child.run_validation(item)
  File "/Users/hongyuanfan/Library/Python/3.9/lib/python/site-packages/rest_framework/serializers.py", line 426, in run_validation
    value = self.to_internal_value(data)
  File "/Users/hongyuanfan/Library/Python/3.9/lib/python/site-packages/rest_framework/serializers.py", line 479, in to_internal_value
    for field in fields:
  File "/Users/hongyuanfan/Library/Python/3.9/lib/python/site-packages/rest_framework/serializers.py", line 362, in _writable_fields
    for field in self.fields.values():
  File "/Users/hongyuanfan/Library/Python/3.9/lib/python/site-packages/django/utils/functional.py", line 57, in __get__
    res = instance.__dict__[self.name] = self.func(instance)
  File "/Users/hongyuanfan/Library/Python/3.9/lib/python/site-packages/rest_framework/serializers.py", line 356, in fields
    for key, value in self.get_fields().items():
  File "/Users/hongyuanfan/Library/Python/3.9/lib/python/site-packages/rest_framework/serializers.py", line 1076, in get_fields
    field_class, field_kwargs = self.build_field(
  File "/Users/hongyuanfan/Library/Python/3.9/lib/python/site-packages/rest_framework/serializers.py", line 1222, in build_field
    return self.build_unknown_field(field_name, model_class)
  File "/Users/hongyuanfan/Library/Python/3.9/lib/python/site-packages/rest_framework/serializers.py", line 1340, in build_unknown_field
    raise ImproperlyConfigured(
django.core.exceptions.ImproperlyConfigured: Field name `dob` is not valid for model `Borrower`.
WARNING 2025-04-21 11:28:20,767 log Not Found: /api/applications/applications/99999/
WARNING 2025-04-21 11:28:20,769 log Bad Request: /api/applications/applications/
WARNING 2025-04-21 11:28:20,771 log Bad Request: /api/applications/applications/1/
WARNING 2025-04-21 11:28:20,773 log Unauthorized: /api/applications/applications/
ERROR 2025-04-21 11:28:24,122 log Internal Server Error: /api/applications/applications/
Traceback (most recent call last):
  File "/Users/hongyuanfan/Library/Python/3.9/lib/python/site-packages/django/core/handlers/exception.py", line 55, in inner
    response = get_response(request)
  File "/Users/hongyuanfan/Library/Python/3.9/lib/python/site-packages/django/core/handlers/base.py", line 197, in _get_response
    response = wrapped_callback(request, *callback_args, **callback_kwargs)
  File "/Users/hongyuanfan/Library/Python/3.9/lib/python/site-packages/django/views/decorators/csrf.py", line 56, in wrapper_view
    return view_func(*args, **kwargs)
  File "/Users/hongyuanfan/Library/Python/3.9/lib/python/site-packages/rest_framework/viewsets.py", line 125, in view
    return self.dispatch(request, *args, **kwargs)
  File "/Users/hongyuanfan/Library/Python/3.9/lib/python/site-packages/rest_framework/views.py", line 509, in dispatch
    response = self.handle_exception(exc)
  File "/Users/hongyuanfan/Library/Python/3.9/lib/python/site-packages/rest_framework/views.py", line 469, in handle_exception
    self.raise_uncaught_exception(exc)
  File "/Users/hongyuanfan/Library/Python/3.9/lib/python/site-packages/rest_framework/views.py", line 480, in raise_uncaught_exception
    raise exc
  File "/Users/hongyuanfan/Library/Python/3.9/lib/python/site-packages/rest_framework/views.py", line 506, in dispatch
    response = handler(request, *args, **kwargs)
  File "/Users/hongyuanfan/Library/Python/3.9/lib/python/site-packages/rest_framework/mixins.py", line 43, in list
    return self.get_paginated_response(serializer.data)
  File "/Users/hongyuanfan/Library/Python/3.9/lib/python/site-packages/rest_framework/serializers.py", line 768, in data
    ret = super().data
  File "/Users/hongyuanfan/Library/Python/3.9/lib/python/site-packages/rest_framework/serializers.py", line 253, in data
    self._data = self.to_representation(self.instance)
  File "/Users/hongyuanfan/Library/Python/3.9/lib/python/site-packages/rest_framework/serializers.py", line 686, in to_representation
    return [
  File "/Users/hongyuanfan/Library/Python/3.9/lib/python/site-packages/rest_framework/serializers.py", line 687, in <listcomp>
    self.child.to_representation(item) for item in iterable
  File "/Users/hongyuanfan/Library/Python/3.9/lib/python/site-packages/rest_framework/serializers.py", line 522, in to_representation
    ret[field.field_name] = field.to_representation(attribute)
  File "/Users/hongyuanfan/Library/Python/3.9/lib/python/site-packages/rest_framework/serializers.py", line 686, in to_representation
    return [
  File "/Users/hongyuanfan/Library/Python/3.9/lib/python/site-packages/rest_framework/serializers.py", line 687, in <listcomp>
    self.child.to_representation(item) for item in iterable
  File "/Users/hongyuanfan/Library/Python/3.9/lib/python/site-packages/rest_framework/serializers.py", line 507, in to_representation
    for field in fields:
  File "/Users/hongyuanfan/Library/Python/3.9/lib/python/site-packages/rest_framework/serializers.py", line 368, in _readable_fields
    for field in self.fields.values():
  File "/Users/hongyuanfan/Library/Python/3.9/lib/python/site-packages/django/utils/functional.py", line 57, in __get__
    res = instance.__dict__[self.name] = self.func(instance)
  File "/Users/hongyuanfan/Library/Python/3.9/lib/python/site-packages/rest_framework/serializers.py", line 356, in fields
    for key, value in self.get_fields().items():
  File "/Users/hongyuanfan/Library/Python/3.9/lib/python/site-packages/rest_framework/serializers.py", line 1076, in get_fields
    field_class, field_kwargs = self.build_field(
  File "/Users/hongyuanfan/Library/Python/3.9/lib/python/site-packages/rest_framework/serializers.py", line 1222, in build_field
    return self.build_unknown_field(field_name, model_class)
  File "/Users/hongyuanfan/Library/Python/3.9/lib/python/site-packages/rest_framework/serializers.py", line 1340, in build_unknown_field
    raise ImproperlyConfigured(
django.core.exceptions.ImproperlyConfigured: Field name `dob` is not valid for model `Borrower`.
ERROR 2025-04-21 11:28:24,812 log Internal Server Error: /api/applications/applications/1/
Traceback (most recent call last):
  File "/Users/hongyuanfan/Library/Python/3.9/lib/python/site-packages/django/core/handlers/exception.py", line 55, in inner
    response = get_response(request)
  File "/Users/hongyuanfan/Library/Python/3.9/lib/python/site-packages/django/core/handlers/base.py", line 197, in _get_response
    response = wrapped_callback(request, *callback_args, **callback_kwargs)
  File "/Users/hongyuanfan/Library/Python/3.9/lib/python/site-packages/django/views/decorators/csrf.py", line 56, in wrapper_view
    return view_func(*args, **kwargs)
  File "/Users/hongyuanfan/Library/Python/3.9/lib/python/site-packages/rest_framework/viewsets.py", line 125, in view
    return self.dispatch(request, *args, **kwargs)
  File "/Users/hongyuanfan/Library/Python/3.9/lib/python/site-packages/rest_framework/views.py", line 509, in dispatch
    response = self.handle_exception(exc)
  File "/Users/hongyuanfan/Library/Python/3.9/lib/python/site-packages/rest_framework/views.py", line 469, in handle_exception
    self.raise_uncaught_exception(exc)
  File "/Users/hongyuanfan/Library/Python/3.9/lib/python/site-packages/rest_framework/views.py", line 480, in raise_uncaught_exception
    raise exc
  File "/Users/hongyuanfan/Library/Python/3.9/lib/python/site-packages/rest_framework/views.py", line 506, in dispatch
    response = handler(request, *args, **kwargs)
  File "/Users/hongyuanfan/Library/Python/3.9/lib/python/site-packages/rest_framework/mixins.py", line 82, in partial_update
    return self.update(request, *args, **kwargs)
  File "/Users/hongyuanfan/Library/Python/3.9/lib/python/site-packages/rest_framework/mixins.py", line 75, in update
    return Response(serializer.data)
  File "/Users/hongyuanfan/Library/Python/3.9/lib/python/site-packages/rest_framework/serializers.py", line 555, in data
    ret = super().data
  File "/Users/hongyuanfan/Library/Python/3.9/lib/python/site-packages/rest_framework/serializers.py", line 253, in data
    self._data = self.to_representation(self.instance)
  File "/Users/hongyuanfan/Library/Python/3.9/lib/python/site-packages/rest_framework/serializers.py", line 522, in to_representation
    ret[field.field_name] = field.to_representation(attribute)
  File "/Users/hongyuanfan/Library/Python/3.9/lib/python/site-packages/rest_framework/serializers.py", line 686, in to_representation
    return [
  File "/Users/hongyuanfan/Library/Python/3.9/lib/python/site-packages/rest_framework/serializers.py", line 687, in <listcomp>
    self.child.to_representation(item) for item in iterable
  File "/Users/hongyuanfan/Library/Python/3.9/lib/python/site-packages/rest_framework/serializers.py", line 507, in to_representation
    for field in fields:
  File "/Users/hongyuanfan/Library/Python/3.9/lib/python/site-packages/rest_framework/serializers.py", line 368, in _readable_fields
    for field in self.fields.values():
  File "/Users/hongyuanfan/Library/Python/3.9/lib/python/site-packages/django/utils/functional.py", line 57, in __get__
    res = instance.__dict__[self.name] = self.func(instance)
  File "/Users/hongyuanfan/Library/Python/3.9/lib/python/site-packages/rest_framework/serializers.py", line 356, in fields
    for key, value in self.get_fields().items():
  File "/Users/hongyuanfan/Library/Python/3.9/lib/python/site-packages/rest_framework/serializers.py", line 1076, in get_fields
    field_class, field_kwargs = self.build_field(
  File "/Users/hongyuanfan/Library/Python/3.9/lib/python/site-packages/rest_framework/serializers.py", line 1222, in build_field
    return self.build_unknown_field(field_name, model_class)
  File "/Users/hongyuanfan/Library/Python/3.9/lib/python/site-packages/rest_framework/serializers.py", line 1340, in build_unknown_field
    raise ImproperlyConfigured(
django.core.exceptions.ImproperlyConfigured: Field name `dob` is not valid for model `Borrower`.
ERROR 2025-04-21 11:28:25,506 log Internal Server Error: /api/applications/applications/1/update_stage/
Traceback (most recent call last):
  File "/Users/hongyuanfan/Library/Python/3.9/lib/python/site-packages/django/core/handlers/exception.py", line 55, in inner
    response = get_response(request)
  File "/Users/hongyuanfan/Library/Python/3.9/lib/python/site-packages/django/core/handlers/base.py", line 197, in _get_response
    response = wrapped_callback(request, *callback_args, **callback_kwargs)
  File "/Users/hongyuanfan/Library/Python/3.9/lib/python/site-packages/django/views/decorators/csrf.py", line 56, in wrapper_view
    return view_func(*args, **kwargs)
  File "/Users/hongyuanfan/Library/Python/3.9/lib/python/site-packages/rest_framework/viewsets.py", line 125, in view
    return self.dispatch(request, *args, **kwargs)
  File "/Users/hongyuanfan/Library/Python/3.9/lib/python/site-packages/rest_framework/views.py", line 509, in dispatch
    response = self.handle_exception(exc)
  File "/Users/hongyuanfan/Library/Python/3.9/lib/python/site-packages/rest_framework/views.py", line 469, in handle_exception
    self.raise_uncaught_exception(exc)
  File "/Users/hongyuanfan/Library/Python/3.9/lib/python/site-packages/rest_framework/views.py", line 480, in raise_uncaught_exception
    raise exc
  File "/Users/hongyuanfan/Library/Python/3.9/lib/python/site-packages/rest_framework/views.py", line 506, in dispatch
    response = handler(request, *args, **kwargs)
  File "/Users/hongyuanfan/Desktop/LoanAPPV3/backenddjango/applications/views.py", line 80, in update_stage
    return Response(ApplicationDetailSerializer(application, context={'request': request}).data)
  File "/Users/hongyuanfan/Library/Python/3.9/lib/python/site-packages/rest_framework/serializers.py", line 555, in data
    ret = super().data
  File "/Users/hongyuanfan/Library/Python/3.9/lib/python/site-packages/rest_framework/serializers.py", line 253, in data
    self._data = self.to_representation(self.instance)
  File "/Users/hongyuanfan/Library/Python/3.9/lib/python/site-packages/rest_framework/serializers.py", line 522, in to_representation
    ret[field.field_name] = field.to_representation(attribute)
  File "/Users/hongyuanfan/Library/Python/3.9/lib/python/site-packages/rest_framework/serializers.py", line 686, in to_representation
    return [
  File "/Users/hongyuanfan/Library/Python/3.9/lib/python/site-packages/rest_framework/serializers.py", line 687, in <listcomp>
    self.child.to_representation(item) for item in iterable
  File "/Users/hongyuanfan/Library/Python/3.9/lib/python/site-packages/rest_framework/serializers.py", line 507, in to_representation
    for field in fields:
  File "/Users/hongyuanfan/Library/Python/3.9/lib/python/site-packages/rest_framework/serializers.py", line 368, in _readable_fields
    for field in self.fields.values():
  File "/Users/hongyuanfan/Library/Python/3.9/lib/python/site-packages/django/utils/functional.py", line 57, in __get__
    res = instance.__dict__[self.name] = self.func(instance)
  File "/Users/hongyuanfan/Library/Python/3.9/lib/python/site-packages/rest_framework/serializers.py", line 356, in fields
    for key, value in self.get_fields().items():
  File "/Users/hongyuanfan/Library/Python/3.9/lib/python/site-packages/rest_framework/serializers.py", line 1076, in get_fields
    field_class, field_kwargs = self.build_field(
  File "/Users/hongyuanfan/Library/Python/3.9/lib/python/site-packages/rest_framework/serializers.py", line 1222, in build_field
    return self.build_unknown_field(field_name, model_class)
  File "/Users/hongyuanfan/Library/Python/3.9/lib/python/site-packages/rest_framework/serializers.py", line 1340, in build_unknown_field
    raise ImproperlyConfigured(
django.core.exceptions.ImproperlyConfigured: Field name `dob` is not valid for model `Borrower`.
INFO 2025-04-21 11:28:26,014 views Login attempt for email: admin@example.com
WARNING 2025-04-21 11:28:26,189 log Unauthorized: /api/users/auth/login/
INFO 2025-04-21 11:28:26,687 views Login attempt for email: admin@example.com
INFO 2025-04-21 11:28:29,364 views Registration attempt with data: {'email': 'admin@example.com', 'password': 'newpassword123', 'first_name': 'Duplicate', 'last_name': 'User', 'role': 'client'}
ERROR 2025-04-21 11:28:29,366 views Registration validation errors: {'email': [ErrorDetail(string='user with this email address already exists.', code='unique')]}
WARNING 2025-04-21 11:28:29,366 log Bad Request: /api/users/auth/register/
INFO 2025-04-21 11:28:29,864 views Registration attempt with data: {'email': 'newuser@example.com', 'password': 'newpassword123', 'first_name': 'New', 'last_name': 'User', 'role': 'client'}
WARNING 2025-04-21 11:28:31,044 log Forbidden: /api/users/users/
WARNING 2025-04-21 11:31:08,318 log Not Found: /api/applications/applications/99999/
WARNING 2025-04-21 11:31:08,319 log Bad Request: /api/applications/applications/
WARNING 2025-04-21 11:31:08,322 log Bad Request: /api/applications/applications/1/
WARNING 2025-04-21 11:31:08,323 log Unauthorized: /api/applications/applications/
WARNING 2025-04-21 11:31:08,329 log Not Found: /api/applications/applications/2/
ERROR 2025-04-21 11:31:08,988 log Internal Server Error: /api/applications/applications/
Traceback (most recent call last):
  File "/Users/hongyuanfan/Library/Python/3.9/lib/python/site-packages/rest_framework/fields.py", line 446, in get_attribute
    return get_attribute(instance, self.source_attrs)
  File "/Users/hongyuanfan/Library/Python/3.9/lib/python/site-packages/rest_framework/fields.py", line 96, in get_attribute
    instance = getattr(instance, attr)
AttributeError: 'Borrower' object has no attribute 'address'

During handling of the above exception, another exception occurred:

Traceback (most recent call last):
  File "/Users/hongyuanfan/Library/Python/3.9/lib/python/site-packages/django/core/handlers/exception.py", line 55, in inner
    response = get_response(request)
  File "/Users/hongyuanfan/Library/Python/3.9/lib/python/site-packages/django/core/handlers/base.py", line 197, in _get_response
    response = wrapped_callback(request, *callback_args, **callback_kwargs)
  File "/Users/hongyuanfan/Library/Python/3.9/lib/python/site-packages/django/views/decorators/csrf.py", line 56, in wrapper_view
    return view_func(*args, **kwargs)
  File "/Users/hongyuanfan/Library/Python/3.9/lib/python/site-packages/rest_framework/viewsets.py", line 125, in view
    return self.dispatch(request, *args, **kwargs)
  File "/Users/hongyuanfan/Library/Python/3.9/lib/python/site-packages/rest_framework/views.py", line 509, in dispatch
    response = self.handle_exception(exc)
  File "/Users/hongyuanfan/Library/Python/3.9/lib/python/site-packages/rest_framework/views.py", line 469, in handle_exception
    self.raise_uncaught_exception(exc)
  File "/Users/hongyuanfan/Library/Python/3.9/lib/python/site-packages/rest_framework/views.py", line 480, in raise_uncaught_exception
    raise exc
  File "/Users/hongyuanfan/Library/Python/3.9/lib/python/site-packages/rest_framework/views.py", line 506, in dispatch
    response = handler(request, *args, **kwargs)
  File "/Users/hongyuanfan/Library/Python/3.9/lib/python/site-packages/rest_framework/mixins.py", line 43, in list
    return self.get_paginated_response(serializer.data)
  File "/Users/hongyuanfan/Library/Python/3.9/lib/python/site-packages/rest_framework/serializers.py", line 768, in data
    ret = super().data
  File "/Users/hongyuanfan/Library/Python/3.9/lib/python/site-packages/rest_framework/serializers.py", line 253, in data
    self._data = self.to_representation(self.instance)
  File "/Users/hongyuanfan/Library/Python/3.9/lib/python/site-packages/rest_framework/serializers.py", line 686, in to_representation
    return [
  File "/Users/hongyuanfan/Library/Python/3.9/lib/python/site-packages/rest_framework/serializers.py", line 687, in <listcomp>
    self.child.to_representation(item) for item in iterable
  File "/Users/hongyuanfan/Library/Python/3.9/lib/python/site-packages/rest_framework/serializers.py", line 522, in to_representation
    ret[field.field_name] = field.to_representation(attribute)
  File "/Users/hongyuanfan/Library/Python/3.9/lib/python/site-packages/rest_framework/serializers.py", line 686, in to_representation
    return [
  File "/Users/hongyuanfan/Library/Python/3.9/lib/python/site-packages/rest_framework/serializers.py", line 687, in <listcomp>
    self.child.to_representation(item) for item in iterable
  File "/Users/hongyuanfan/Library/Python/3.9/lib/python/site-packages/rest_framework/serializers.py", line 509, in to_representation
    attribute = field.get_attribute(instance)
  File "/Users/hongyuanfan/Library/Python/3.9/lib/python/site-packages/rest_framework/fields.py", line 479, in get_attribute
    raise type(exc)(msg)
AttributeError: Got AttributeError when attempting to get a value for field `address` on serializer `BorrowerSerializer`.
The serializer field might be named incorrectly and not match any attribute or key on the `Borrower` instance.
Original exception text was: 'Borrower' object has no attribute 'address'.
INFO 2025-04-21 11:31:10,324 views Login attempt for email: admin@example.com
ERROR 2025-04-21 11:31:10,527 log Internal Server Error: /api/applications/applications/
Traceback (most recent call last):
  File "/Users/hongyuanfan/Library/Python/3.9/lib/python/site-packages/rest_framework/fields.py", line 446, in get_attribute
    return get_attribute(instance, self.source_attrs)
  File "/Users/hongyuanfan/Library/Python/3.9/lib/python/site-packages/rest_framework/fields.py", line 96, in get_attribute
    instance = getattr(instance, attr)
AttributeError: 'Borrower' object has no attribute 'address'

During handling of the above exception, another exception occurred:

Traceback (most recent call last):
  File "/Users/hongyuanfan/Library/Python/3.9/lib/python/site-packages/django/core/handlers/exception.py", line 55, in inner
    response = get_response(request)
  File "/Users/hongyuanfan/Library/Python/3.9/lib/python/site-packages/django/core/handlers/base.py", line 197, in _get_response
    response = wrapped_callback(request, *callback_args, **callback_kwargs)
  File "/Users/hongyuanfan/Library/Python/3.9/lib/python/site-packages/django/views/decorators/csrf.py", line 56, in wrapper_view
    return view_func(*args, **kwargs)
  File "/Users/hongyuanfan/Library/Python/3.9/lib/python/site-packages/rest_framework/viewsets.py", line 125, in view
    return self.dispatch(request, *args, **kwargs)
  File "/Users/hongyuanfan/Library/Python/3.9/lib/python/site-packages/rest_framework/views.py", line 509, in dispatch
    response = self.handle_exception(exc)
  File "/Users/hongyuanfan/Library/Python/3.9/lib/python/site-packages/rest_framework/views.py", line 469, in handle_exception
    self.raise_uncaught_exception(exc)
  File "/Users/hongyuanfan/Library/Python/3.9/lib/python/site-packages/rest_framework/views.py", line 480, in raise_uncaught_exception
    raise exc
  File "/Users/hongyuanfan/Library/Python/3.9/lib/python/site-packages/rest_framework/views.py", line 506, in dispatch
    response = handler(request, *args, **kwargs)
  File "/Users/hongyuanfan/Library/Python/3.9/lib/python/site-packages/rest_framework/mixins.py", line 43, in list
    return self.get_paginated_response(serializer.data)
  File "/Users/hongyuanfan/Library/Python/3.9/lib/python/site-packages/rest_framework/serializers.py", line 768, in data
    ret = super().data
  File "/Users/hongyuanfan/Library/Python/3.9/lib/python/site-packages/rest_framework/serializers.py", line 253, in data
    self._data = self.to_representation(self.instance)
  File "/Users/hongyuanfan/Library/Python/3.9/lib/python/site-packages/rest_framework/serializers.py", line 686, in to_representation
    return [
  File "/Users/hongyuanfan/Library/Python/3.9/lib/python/site-packages/rest_framework/serializers.py", line 687, in <listcomp>
    self.child.to_representation(item) for item in iterable
  File "/Users/hongyuanfan/Library/Python/3.9/lib/python/site-packages/rest_framework/serializers.py", line 522, in to_representation
    ret[field.field_name] = field.to_representation(attribute)
  File "/Users/hongyuanfan/Library/Python/3.9/lib/python/site-packages/rest_framework/serializers.py", line 686, in to_representation
    return [
  File "/Users/hongyuanfan/Library/Python/3.9/lib/python/site-packages/rest_framework/serializers.py", line 687, in <listcomp>
    self.child.to_representation(item) for item in iterable
  File "/Users/hongyuanfan/Library/Python/3.9/lib/python/site-packages/rest_framework/serializers.py", line 509, in to_representation
    attribute = field.get_attribute(instance)
  File "/Users/hongyuanfan/Library/Python/3.9/lib/python/site-packages/rest_framework/fields.py", line 479, in get_attribute
    raise type(exc)(msg)
AttributeError: Got AttributeError when attempting to get a value for field `address` on serializer `BorrowerSerializer`.
The serializer field might be named incorrectly and not match any attribute or key on the `Borrower` instance.
Original exception text was: 'Borrower' object has no attribute 'address'.
WARNING 2025-04-21 11:31:11,196 log Bad Request: /api/applications/applications/
WARNING 2025-04-21 11:31:11,862 log Bad Request: /api/applications/applications/
ERROR 2025-04-21 11:31:12,530 log Internal Server Error: /api/applications/applications/
Traceback (most recent call last):
  File "/Users/hongyuanfan/Library/Python/3.9/lib/python/site-packages/rest_framework/fields.py", line 446, in get_attribute
    return get_attribute(instance, self.source_attrs)
  File "/Users/hongyuanfan/Library/Python/3.9/lib/python/site-packages/rest_framework/fields.py", line 96, in get_attribute
    instance = getattr(instance, attr)
AttributeError: 'Borrower' object has no attribute 'address'

During handling of the above exception, another exception occurred:

Traceback (most recent call last):
  File "/Users/hongyuanfan/Library/Python/3.9/lib/python/site-packages/django/core/handlers/exception.py", line 55, in inner
    response = get_response(request)
  File "/Users/hongyuanfan/Library/Python/3.9/lib/python/site-packages/django/core/handlers/base.py", line 197, in _get_response
    response = wrapped_callback(request, *callback_args, **callback_kwargs)
  File "/Users/hongyuanfan/Library/Python/3.9/lib/python/site-packages/django/views/decorators/csrf.py", line 56, in wrapper_view
    return view_func(*args, **kwargs)
  File "/Users/hongyuanfan/Library/Python/3.9/lib/python/site-packages/rest_framework/viewsets.py", line 125, in view
    return self.dispatch(request, *args, **kwargs)
  File "/Users/hongyuanfan/Library/Python/3.9/lib/python/site-packages/rest_framework/views.py", line 509, in dispatch
    response = self.handle_exception(exc)
  File "/Users/hongyuanfan/Library/Python/3.9/lib/python/site-packages/rest_framework/views.py", line 469, in handle_exception
    self.raise_uncaught_exception(exc)
  File "/Users/hongyuanfan/Library/Python/3.9/lib/python/site-packages/rest_framework/views.py", line 480, in raise_uncaught_exception
    raise exc
  File "/Users/hongyuanfan/Library/Python/3.9/lib/python/site-packages/rest_framework/views.py", line 506, in dispatch
    response = handler(request, *args, **kwargs)
  File "/Users/hongyuanfan/Library/Python/3.9/lib/python/site-packages/rest_framework/mixins.py", line 43, in list
    return self.get_paginated_response(serializer.data)
  File "/Users/hongyuanfan/Library/Python/3.9/lib/python/site-packages/rest_framework/serializers.py", line 768, in data
    ret = super().data
  File "/Users/hongyuanfan/Library/Python/3.9/lib/python/site-packages/rest_framework/serializers.py", line 253, in data
    self._data = self.to_representation(self.instance)
  File "/Users/hongyuanfan/Library/Python/3.9/lib/python/site-packages/rest_framework/serializers.py", line 686, in to_representation
    return [
  File "/Users/hongyuanfan/Library/Python/3.9/lib/python/site-packages/rest_framework/serializers.py", line 687, in <listcomp>
    self.child.to_representation(item) for item in iterable
  File "/Users/hongyuanfan/Library/Python/3.9/lib/python/site-packages/rest_framework/serializers.py", line 522, in to_representation
    ret[field.field_name] = field.to_representation(attribute)
  File "/Users/hongyuanfan/Library/Python/3.9/lib/python/site-packages/rest_framework/serializers.py", line 686, in to_representation
    return [
  File "/Users/hongyuanfan/Library/Python/3.9/lib/python/site-packages/rest_framework/serializers.py", line 687, in <listcomp>
    self.child.to_representation(item) for item in iterable
  File "/Users/hongyuanfan/Library/Python/3.9/lib/python/site-packages/rest_framework/serializers.py", line 509, in to_representation
    attribute = field.get_attribute(instance)
  File "/Users/hongyuanfan/Library/Python/3.9/lib/python/site-packages/rest_framework/fields.py", line 479, in get_attribute
    raise type(exc)(msg)
AttributeError: Got AttributeError when attempting to get a value for field `address` on serializer `BorrowerSerializer`.
The serializer field might be named incorrectly and not match any attribute or key on the `Borrower` instance.
Original exception text was: 'Borrower' object has no attribute 'address'.
WARNING 2025-04-21 11:31:13,876 log Bad Request: /api/applications/applications/1/add_fee/
WARNING 2025-04-21 11:31:15,210 log Bad Request: /api/applications/applications/1/add_repayment/
ERROR 2025-04-21 11:31:15,870 log Internal Server Error: /api/applications/applications/1/
Traceback (most recent call last):
  File "/Users/hongyuanfan/Library/Python/3.9/lib/python/site-packages/rest_framework/fields.py", line 446, in get_attribute
    return get_attribute(instance, self.source_attrs)
  File "/Users/hongyuanfan/Library/Python/3.9/lib/python/site-packages/rest_framework/fields.py", line 96, in get_attribute
    instance = getattr(instance, attr)
AttributeError: 'Borrower' object has no attribute 'address'

During handling of the above exception, another exception occurred:

Traceback (most recent call last):
  File "/Users/hongyuanfan/Library/Python/3.9/lib/python/site-packages/django/core/handlers/exception.py", line 55, in inner
    response = get_response(request)
  File "/Users/hongyuanfan/Library/Python/3.9/lib/python/site-packages/django/core/handlers/base.py", line 197, in _get_response
    response = wrapped_callback(request, *callback_args, **callback_kwargs)
  File "/Users/hongyuanfan/Library/Python/3.9/lib/python/site-packages/django/views/decorators/csrf.py", line 56, in wrapper_view
    return view_func(*args, **kwargs)
  File "/Users/hongyuanfan/Library/Python/3.9/lib/python/site-packages/rest_framework/viewsets.py", line 125, in view
    return self.dispatch(request, *args, **kwargs)
  File "/Users/hongyuanfan/Library/Python/3.9/lib/python/site-packages/rest_framework/views.py", line 509, in dispatch
    response = self.handle_exception(exc)
  File "/Users/hongyuanfan/Library/Python/3.9/lib/python/site-packages/rest_framework/views.py", line 469, in handle_exception
    self.raise_uncaught_exception(exc)
  File "/Users/hongyuanfan/Library/Python/3.9/lib/python/site-packages/rest_framework/views.py", line 480, in raise_uncaught_exception
    raise exc
  File "/Users/hongyuanfan/Library/Python/3.9/lib/python/site-packages/rest_framework/views.py", line 506, in dispatch
    response = handler(request, *args, **kwargs)
  File "/Users/hongyuanfan/Library/Python/3.9/lib/python/site-packages/rest_framework/mixins.py", line 56, in retrieve
    return Response(serializer.data)
  File "/Users/hongyuanfan/Library/Python/3.9/lib/python/site-packages/rest_framework/serializers.py", line 555, in data
    ret = super().data
  File "/Users/hongyuanfan/Library/Python/3.9/lib/python/site-packages/rest_framework/serializers.py", line 253, in data
    self._data = self.to_representation(self.instance)
  File "/Users/hongyuanfan/Library/Python/3.9/lib/python/site-packages/rest_framework/serializers.py", line 522, in to_representation
    ret[field.field_name] = field.to_representation(attribute)
  File "/Users/hongyuanfan/Library/Python/3.9/lib/python/site-packages/rest_framework/serializers.py", line 686, in to_representation
    return [
  File "/Users/hongyuanfan/Library/Python/3.9/lib/python/site-packages/rest_framework/serializers.py", line 687, in <listcomp>
    self.child.to_representation(item) for item in iterable
  File "/Users/hongyuanfan/Library/Python/3.9/lib/python/site-packages/rest_framework/serializers.py", line 509, in to_representation
    attribute = field.get_attribute(instance)
  File "/Users/hongyuanfan/Library/Python/3.9/lib/python/site-packages/rest_framework/fields.py", line 479, in get_attribute
    raise type(exc)(msg)
AttributeError: Got AttributeError when attempting to get a value for field `address` on serializer `BorrowerSerializer`.
The serializer field might be named incorrectly and not match any attribute or key on the `Borrower` instance.
Original exception text was: 'Borrower' object has no attribute 'address'.
ERROR 2025-04-21 11:31:16,530 log Internal Server Error: /api/applications/applications/
Traceback (most recent call last):
  File "/Users/hongyuanfan/Library/Python/3.9/lib/python/site-packages/rest_framework/fields.py", line 446, in get_attribute
    return get_attribute(instance, self.source_attrs)
  File "/Users/hongyuanfan/Library/Python/3.9/lib/python/site-packages/rest_framework/fields.py", line 96, in get_attribute
    instance = getattr(instance, attr)
AttributeError: 'Borrower' object has no attribute 'address'

During handling of the above exception, another exception occurred:

Traceback (most recent call last):
  File "/Users/hongyuanfan/Library/Python/3.9/lib/python/site-packages/django/core/handlers/exception.py", line 55, in inner
    response = get_response(request)
  File "/Users/hongyuanfan/Library/Python/3.9/lib/python/site-packages/django/core/handlers/base.py", line 197, in _get_response
    response = wrapped_callback(request, *callback_args, **callback_kwargs)
  File "/Users/hongyuanfan/Library/Python/3.9/lib/python/site-packages/django/views/decorators/csrf.py", line 56, in wrapper_view
    return view_func(*args, **kwargs)
  File "/Users/hongyuanfan/Library/Python/3.9/lib/python/site-packages/rest_framework/viewsets.py", line 125, in view
    return self.dispatch(request, *args, **kwargs)
  File "/Users/hongyuanfan/Library/Python/3.9/lib/python/site-packages/rest_framework/views.py", line 509, in dispatch
    response = self.handle_exception(exc)
  File "/Users/hongyuanfan/Library/Python/3.9/lib/python/site-packages/rest_framework/views.py", line 469, in handle_exception
    self.raise_uncaught_exception(exc)
  File "/Users/hongyuanfan/Library/Python/3.9/lib/python/site-packages/rest_framework/views.py", line 480, in raise_uncaught_exception
    raise exc
  File "/Users/hongyuanfan/Library/Python/3.9/lib/python/site-packages/rest_framework/views.py", line 506, in dispatch
    response = handler(request, *args, **kwargs)
  File "/Users/hongyuanfan/Library/Python/3.9/lib/python/site-packages/rest_framework/mixins.py", line 43, in list
    return self.get_paginated_response(serializer.data)
  File "/Users/hongyuanfan/Library/Python/3.9/lib/python/site-packages/rest_framework/serializers.py", line 768, in data
    ret = super().data
  File "/Users/hongyuanfan/Library/Python/3.9/lib/python/site-packages/rest_framework/serializers.py", line 253, in data
    self._data = self.to_representation(self.instance)
  File "/Users/hongyuanfan/Library/Python/3.9/lib/python/site-packages/rest_framework/serializers.py", line 686, in to_representation
    return [
  File "/Users/hongyuanfan/Library/Python/3.9/lib/python/site-packages/rest_framework/serializers.py", line 687, in <listcomp>
    self.child.to_representation(item) for item in iterable
  File "/Users/hongyuanfan/Library/Python/3.9/lib/python/site-packages/rest_framework/serializers.py", line 522, in to_representation
    ret[field.field_name] = field.to_representation(attribute)
  File "/Users/hongyuanfan/Library/Python/3.9/lib/python/site-packages/rest_framework/serializers.py", line 686, in to_representation
    return [
  File "/Users/hongyuanfan/Library/Python/3.9/lib/python/site-packages/rest_framework/serializers.py", line 687, in <listcomp>
    self.child.to_representation(item) for item in iterable
  File "/Users/hongyuanfan/Library/Python/3.9/lib/python/site-packages/rest_framework/serializers.py", line 509, in to_representation
    attribute = field.get_attribute(instance)
  File "/Users/hongyuanfan/Library/Python/3.9/lib/python/site-packages/rest_framework/fields.py", line 479, in get_attribute
    raise type(exc)(msg)
AttributeError: Got AttributeError when attempting to get a value for field `address` on serializer `BorrowerSerializer`.
The serializer field might be named incorrectly and not match any attribute or key on the `Borrower` instance.
Original exception text was: 'Borrower' object has no attribute 'address'.
WARNING 2025-04-21 11:31:17,193 log Bad Request: /api/applications/applications/
WARNING 2025-04-21 11:31:17,854 log Not Found: /api/applications/applications/99999/
WARNING 2025-04-21 11:31:17,855 log Bad Request: /api/applications/applications/
WARNING 2025-04-21 11:31:17,858 log Bad Request: /api/applications/applications/1/
WARNING 2025-04-21 11:31:17,859 log Unauthorized: /api/applications/applications/
ERROR 2025-04-21 11:31:21,184 log Internal Server Error: /api/applications/applications/
Traceback (most recent call last):
  File "/Users/hongyuanfan/Library/Python/3.9/lib/python/site-packages/rest_framework/fields.py", line 446, in get_attribute
    return get_attribute(instance, self.source_attrs)
  File "/Users/hongyuanfan/Library/Python/3.9/lib/python/site-packages/rest_framework/fields.py", line 96, in get_attribute
    instance = getattr(instance, attr)
AttributeError: 'Borrower' object has no attribute 'address'

During handling of the above exception, another exception occurred:

Traceback (most recent call last):
  File "/Users/hongyuanfan/Library/Python/3.9/lib/python/site-packages/django/core/handlers/exception.py", line 55, in inner
    response = get_response(request)
  File "/Users/hongyuanfan/Library/Python/3.9/lib/python/site-packages/django/core/handlers/base.py", line 197, in _get_response
    response = wrapped_callback(request, *callback_args, **callback_kwargs)
  File "/Users/hongyuanfan/Library/Python/3.9/lib/python/site-packages/django/views/decorators/csrf.py", line 56, in wrapper_view
    return view_func(*args, **kwargs)
  File "/Users/hongyuanfan/Library/Python/3.9/lib/python/site-packages/rest_framework/viewsets.py", line 125, in view
    return self.dispatch(request, *args, **kwargs)
  File "/Users/hongyuanfan/Library/Python/3.9/lib/python/site-packages/rest_framework/views.py", line 509, in dispatch
    response = self.handle_exception(exc)
  File "/Users/hongyuanfan/Library/Python/3.9/lib/python/site-packages/rest_framework/views.py", line 469, in handle_exception
    self.raise_uncaught_exception(exc)
  File "/Users/hongyuanfan/Library/Python/3.9/lib/python/site-packages/rest_framework/views.py", line 480, in raise_uncaught_exception
    raise exc
  File "/Users/hongyuanfan/Library/Python/3.9/lib/python/site-packages/rest_framework/views.py", line 506, in dispatch
    response = handler(request, *args, **kwargs)
  File "/Users/hongyuanfan/Library/Python/3.9/lib/python/site-packages/rest_framework/mixins.py", line 43, in list
    return self.get_paginated_response(serializer.data)
  File "/Users/hongyuanfan/Library/Python/3.9/lib/python/site-packages/rest_framework/serializers.py", line 768, in data
    ret = super().data
  File "/Users/hongyuanfan/Library/Python/3.9/lib/python/site-packages/rest_framework/serializers.py", line 253, in data
    self._data = self.to_representation(self.instance)
  File "/Users/hongyuanfan/Library/Python/3.9/lib/python/site-packages/rest_framework/serializers.py", line 686, in to_representation
    return [
  File "/Users/hongyuanfan/Library/Python/3.9/lib/python/site-packages/rest_framework/serializers.py", line 687, in <listcomp>
    self.child.to_representation(item) for item in iterable
  File "/Users/hongyuanfan/Library/Python/3.9/lib/python/site-packages/rest_framework/serializers.py", line 522, in to_representation
    ret[field.field_name] = field.to_representation(attribute)
  File "/Users/hongyuanfan/Library/Python/3.9/lib/python/site-packages/rest_framework/serializers.py", line 686, in to_representation
    return [
  File "/Users/hongyuanfan/Library/Python/3.9/lib/python/site-packages/rest_framework/serializers.py", line 687, in <listcomp>
    self.child.to_representation(item) for item in iterable
  File "/Users/hongyuanfan/Library/Python/3.9/lib/python/site-packages/rest_framework/serializers.py", line 509, in to_representation
    attribute = field.get_attribute(instance)
  File "/Users/hongyuanfan/Library/Python/3.9/lib/python/site-packages/rest_framework/fields.py", line 479, in get_attribute
    raise type(exc)(msg)
AttributeError: Got AttributeError when attempting to get a value for field `address` on serializer `BorrowerSerializer`.
The serializer field might be named incorrectly and not match any attribute or key on the `Borrower` instance.
Original exception text was: 'Borrower' object has no attribute 'address'.
ERROR 2025-04-21 11:31:21,845 log Internal Server Error: /api/applications/applications/1/
Traceback (most recent call last):
  File "/Users/hongyuanfan/Library/Python/3.9/lib/python/site-packages/rest_framework/fields.py", line 446, in get_attribute
    return get_attribute(instance, self.source_attrs)
  File "/Users/hongyuanfan/Library/Python/3.9/lib/python/site-packages/rest_framework/fields.py", line 96, in get_attribute
    instance = getattr(instance, attr)
AttributeError: 'Borrower' object has no attribute 'address'

During handling of the above exception, another exception occurred:

Traceback (most recent call last):
  File "/Users/hongyuanfan/Library/Python/3.9/lib/python/site-packages/django/core/handlers/exception.py", line 55, in inner
    response = get_response(request)
  File "/Users/hongyuanfan/Library/Python/3.9/lib/python/site-packages/django/core/handlers/base.py", line 197, in _get_response
    response = wrapped_callback(request, *callback_args, **callback_kwargs)
  File "/Users/hongyuanfan/Library/Python/3.9/lib/python/site-packages/django/views/decorators/csrf.py", line 56, in wrapper_view
    return view_func(*args, **kwargs)
  File "/Users/hongyuanfan/Library/Python/3.9/lib/python/site-packages/rest_framework/viewsets.py", line 125, in view
    return self.dispatch(request, *args, **kwargs)
  File "/Users/hongyuanfan/Library/Python/3.9/lib/python/site-packages/rest_framework/views.py", line 509, in dispatch
    response = self.handle_exception(exc)
  File "/Users/hongyuanfan/Library/Python/3.9/lib/python/site-packages/rest_framework/views.py", line 469, in handle_exception
    self.raise_uncaught_exception(exc)
  File "/Users/hongyuanfan/Library/Python/3.9/lib/python/site-packages/rest_framework/views.py", line 480, in raise_uncaught_exception
    raise exc
  File "/Users/hongyuanfan/Library/Python/3.9/lib/python/site-packages/rest_framework/views.py", line 506, in dispatch
    response = handler(request, *args, **kwargs)
  File "/Users/hongyuanfan/Library/Python/3.9/lib/python/site-packages/rest_framework/mixins.py", line 82, in partial_update
    return self.update(request, *args, **kwargs)
  File "/Users/hongyuanfan/Library/Python/3.9/lib/python/site-packages/rest_framework/mixins.py", line 75, in update
    return Response(serializer.data)
  File "/Users/hongyuanfan/Library/Python/3.9/lib/python/site-packages/rest_framework/serializers.py", line 555, in data
    ret = super().data
  File "/Users/hongyuanfan/Library/Python/3.9/lib/python/site-packages/rest_framework/serializers.py", line 253, in data
    self._data = self.to_representation(self.instance)
  File "/Users/hongyuanfan/Library/Python/3.9/lib/python/site-packages/rest_framework/serializers.py", line 522, in to_representation
    ret[field.field_name] = field.to_representation(attribute)
  File "/Users/hongyuanfan/Library/Python/3.9/lib/python/site-packages/rest_framework/serializers.py", line 686, in to_representation
    return [
  File "/Users/hongyuanfan/Library/Python/3.9/lib/python/site-packages/rest_framework/serializers.py", line 687, in <listcomp>
    self.child.to_representation(item) for item in iterable
  File "/Users/hongyuanfan/Library/Python/3.9/lib/python/site-packages/rest_framework/serializers.py", line 509, in to_representation
    attribute = field.get_attribute(instance)
  File "/Users/hongyuanfan/Library/Python/3.9/lib/python/site-packages/rest_framework/fields.py", line 479, in get_attribute
    raise type(exc)(msg)
AttributeError: Got AttributeError when attempting to get a value for field `address` on serializer `BorrowerSerializer`.
The serializer field might be named incorrectly and not match any attribute or key on the `Borrower` instance.
Original exception text was: 'Borrower' object has no attribute 'address'.
ERROR 2025-04-21 11:31:22,676 log Internal Server Error: /api/applications/applications/1/update_stage/
Traceback (most recent call last):
  File "/Users/hongyuanfan/Library/Python/3.9/lib/python/site-packages/rest_framework/fields.py", line 446, in get_attribute
    return get_attribute(instance, self.source_attrs)
  File "/Users/hongyuanfan/Library/Python/3.9/lib/python/site-packages/rest_framework/fields.py", line 96, in get_attribute
    instance = getattr(instance, attr)
AttributeError: 'Borrower' object has no attribute 'address'

During handling of the above exception, another exception occurred:

Traceback (most recent call last):
  File "/Users/hongyuanfan/Library/Python/3.9/lib/python/site-packages/django/core/handlers/exception.py", line 55, in inner
    response = get_response(request)
  File "/Users/hongyuanfan/Library/Python/3.9/lib/python/site-packages/django/core/handlers/base.py", line 197, in _get_response
    response = wrapped_callback(request, *callback_args, **callback_kwargs)
  File "/Users/hongyuanfan/Library/Python/3.9/lib/python/site-packages/django/views/decorators/csrf.py", line 56, in wrapper_view
    return view_func(*args, **kwargs)
  File "/Users/hongyuanfan/Library/Python/3.9/lib/python/site-packages/rest_framework/viewsets.py", line 125, in view
    return self.dispatch(request, *args, **kwargs)
  File "/Users/hongyuanfan/Library/Python/3.9/lib/python/site-packages/rest_framework/views.py", line 509, in dispatch
    response = self.handle_exception(exc)
  File "/Users/hongyuanfan/Library/Python/3.9/lib/python/site-packages/rest_framework/views.py", line 469, in handle_exception
    self.raise_uncaught_exception(exc)
  File "/Users/hongyuanfan/Library/Python/3.9/lib/python/site-packages/rest_framework/views.py", line 480, in raise_uncaught_exception
    raise exc
  File "/Users/hongyuanfan/Library/Python/3.9/lib/python/site-packages/rest_framework/views.py", line 506, in dispatch
    response = handler(request, *args, **kwargs)
  File "/Users/hongyuanfan/Desktop/LoanAPPV3/backenddjango/applications/views.py", line 80, in update_stage
    return Response(ApplicationDetailSerializer(application, context={'request': request}).data)
  File "/Users/hongyuanfan/Library/Python/3.9/lib/python/site-packages/rest_framework/serializers.py", line 555, in data
    ret = super().data
  File "/Users/hongyuanfan/Library/Python/3.9/lib/python/site-packages/rest_framework/serializers.py", line 253, in data
    self._data = self.to_representation(self.instance)
  File "/Users/hongyuanfan/Library/Python/3.9/lib/python/site-packages/rest_framework/serializers.py", line 522, in to_representation
    ret[field.field_name] = field.to_representation(attribute)
  File "/Users/hongyuanfan/Library/Python/3.9/lib/python/site-packages/rest_framework/serializers.py", line 686, in to_representation
    return [
  File "/Users/hongyuanfan/Library/Python/3.9/lib/python/site-packages/rest_framework/serializers.py", line 687, in <listcomp>
    self.child.to_representation(item) for item in iterable
  File "/Users/hongyuanfan/Library/Python/3.9/lib/python/site-packages/rest_framework/serializers.py", line 509, in to_representation
    attribute = field.get_attribute(instance)
  File "/Users/hongyuanfan/Library/Python/3.9/lib/python/site-packages/rest_framework/fields.py", line 479, in get_attribute
    raise type(exc)(msg)
AttributeError: Got AttributeError when attempting to get a value for field `address` on serializer `BorrowerSerializer`.
The serializer field might be named incorrectly and not match any attribute or key on the `Borrower` instance.
Original exception text was: 'Borrower' object has no attribute 'address'.
INFO 2025-04-21 11:31:23,182 views Login attempt for email: admin@example.com
WARNING 2025-04-21 11:31:23,348 log Unauthorized: /api/users/auth/login/
INFO 2025-04-21 11:31:23,844 views Login attempt for email: admin@example.com
INFO 2025-04-21 11:31:26,502 views Registration attempt with data: {'email': 'admin@example.com', 'password': 'newpassword123', 'first_name': 'Duplicate', 'last_name': 'User', 'role': 'client'}
ERROR 2025-04-21 11:31:26,503 views Registration validation errors: {'email': [ErrorDetail(string='user with this email address already exists.', code='unique')]}
WARNING 2025-04-21 11:31:26,504 log Bad Request: /api/users/auth/register/
INFO 2025-04-21 11:31:27,003 views Registration attempt with data: {'email': 'newuser@example.com', 'password': 'newpassword123', 'first_name': 'New', 'last_name': 'User', 'role': 'client'}
WARNING 2025-04-21 11:31:28,171 log Forbidden: /api/users/users/
WARNING 2025-04-21 11:33:52,336 log Not Found: /api/applications/applications/99999/
WARNING 2025-04-21 11:33:52,338 log Bad Request: /api/applications/applications/
WARNING 2025-04-21 11:33:52,340 log Bad Request: /api/applications/applications/1/
WARNING 2025-04-21 11:33:52,341 log Unauthorized: /api/applications/applications/
WARNING 2025-04-21 11:33:52,347 log Not Found: /api/applications/applications/2/
INFO 2025-04-21 11:33:54,360 views Login attempt for email: admin@example.com
WARNING 2025-04-21 11:33:55,471 log Bad Request: /api/applications/applications/2/add_fee/
WARNING 2025-04-21 11:33:58,176 log Bad Request: /api/applications/applications/1/add_fee/
WARNING 2025-04-21 11:33:59,517 log Bad Request: /api/applications/applications/1/add_repayment/
WARNING 2025-04-21 11:34:02,172 log Not Found: /api/applications/applications/99999/
WARNING 2025-04-21 11:34:02,173 log Bad Request: /api/applications/applications/
WARNING 2025-04-21 11:34:02,175 log Bad Request: /api/applications/applications/1/
WARNING 2025-04-21 11:34:02,177 log Unauthorized: /api/applications/applications/
INFO 2025-04-21 11:34:07,284 views Login attempt for email: admin@example.com
WARNING 2025-04-21 11:34:07,449 log Unauthorized: /api/users/auth/login/
INFO 2025-04-21 11:34:07,938 views Login attempt for email: admin@example.com
INFO 2025-04-21 11:34:10,562 views Registration attempt with data: {'email': 'admin@example.com', 'password': 'newpassword123', 'first_name': 'Duplicate', 'last_name': 'User', 'role': 'client'}
ERROR 2025-04-21 11:34:10,563 views Registration validation errors: {'email': [ErrorDetail(string='user with this email address already exists.', code='unique')]}
WARNING 2025-04-21 11:34:10,563 log Bad Request: /api/users/auth/register/
INFO 2025-04-21 11:34:11,050 views Registration attempt with data: {'email': 'newuser@example.com', 'password': 'newpassword123', 'first_name': 'New', 'last_name': 'User', 'role': 'client'}
WARNING 2025-04-21 11:34:12,196 log Forbidden: /api/users/users/
WARNING 2025-04-21 11:40:21,355 log Forbidden: /api/applications/create-with-cascade/
WARNING 2025-04-21 11:40:21,693 log Not Found: /api/applications/1/signature/
WARNING 2025-04-21 11:40:22,355 log Not Found: /api/applications/applications/99999/
WARNING 2025-04-21 11:40:22,356 log Bad Request: /api/applications/applications/
WARNING 2025-04-21 11:40:22,358 log Bad Request: /api/applications/applications/1/
WARNING 2025-04-21 11:40:22,360 log Unauthorized: /api/applications/applications/
WARNING 2025-04-21 11:40:22,365 log Not Found: /api/applications/applications/2/
INFO 2025-04-21 11:40:24,359 views Login attempt for email: admin@example.com
WARNING 2025-04-21 11:40:25,446 log Bad Request: /api/applications/applications/2/add_fee/
WARNING 2025-04-21 11:40:28,153 log Bad Request: /api/applications/applications/1/add_fee/
WARNING 2025-04-21 11:40:29,467 log Bad Request: /api/applications/applications/1/add_repayment/
WARNING 2025-04-21 11:40:32,092 log Not Found: /api/applications/applications/99999/
WARNING 2025-04-21 11:40:32,093 log Bad Request: /api/applications/applications/
WARNING 2025-04-21 11:40:32,095 log Bad Request: /api/applications/applications/1/
WARNING 2025-04-21 11:40:32,096 log Unauthorized: /api/applications/applications/
ERROR 2025-04-21 11:40:32,761 log Internal Server Error: /api/applications/applications/1/fees/
Traceback (most recent call last):
  File "/Users/hongyuanfan/Library/Python/3.9/lib/python/site-packages/django/core/handlers/exception.py", line 55, in inner
    response = get_response(request)
  File "/Users/hongyuanfan/Library/Python/3.9/lib/python/site-packages/django/core/handlers/base.py", line 197, in _get_response
    response = wrapped_callback(request, *callback_args, **callback_kwargs)
  File "/Users/hongyuanfan/Library/Python/3.9/lib/python/site-packages/django/views/decorators/csrf.py", line 56, in wrapper_view
    return view_func(*args, **kwargs)
  File "/Users/hongyuanfan/Library/Python/3.9/lib/python/site-packages/rest_framework/viewsets.py", line 125, in view
    return self.dispatch(request, *args, **kwargs)
  File "/Users/hongyuanfan/Library/Python/3.9/lib/python/site-packages/rest_framework/views.py", line 509, in dispatch
    response = self.handle_exception(exc)
  File "/Users/hongyuanfan/Library/Python/3.9/lib/python/site-packages/rest_framework/views.py", line 469, in handle_exception
    self.raise_uncaught_exception(exc)
  File "/Users/hongyuanfan/Library/Python/3.9/lib/python/site-packages/rest_framework/views.py", line 480, in raise_uncaught_exception
    raise exc
  File "/Users/hongyuanfan/Library/Python/3.9/lib/python/site-packages/rest_framework/views.py", line 506, in dispatch
    response = handler(request, *args, **kwargs)
  File "/Users/hongyuanfan/Desktop/LoanAPPV3/backenddjango/applications/views.py", line 206, in fees
    return Response(serializer.data)
  File "/Users/hongyuanfan/Library/Python/3.9/lib/python/site-packages/rest_framework/serializers.py", line 768, in data
    ret = super().data
  File "/Users/hongyuanfan/Library/Python/3.9/lib/python/site-packages/rest_framework/serializers.py", line 253, in data
    self._data = self.to_representation(self.instance)
  File "/Users/hongyuanfan/Library/Python/3.9/lib/python/site-packages/rest_framework/serializers.py", line 686, in to_representation
    return [
  File "/Users/hongyuanfan/Library/Python/3.9/lib/python/site-packages/rest_framework/serializers.py", line 687, in <listcomp>
    self.child.to_representation(item) for item in iterable
  File "/Users/hongyuanfan/Library/Python/3.9/lib/python/site-packages/rest_framework/serializers.py", line 522, in to_representation
    ret[field.field_name] = field.to_representation(attribute)
  File "/Users/hongyuanfan/Library/Python/3.9/lib/python/site-packages/rest_framework/fields.py", line 1838, in to_representation
    return method(value)
  File "/Users/hongyuanfan/Desktop/LoanAPPV3/backenddjango/documents/serializers.py", line 53, in get_status
    return 'paid' if obj.paid_date else 'waiting'
AttributeError: 'Fee' object has no attribute 'paid_date'
INFO 2025-04-21 11:40:37,210 views Login attempt for email: admin@example.com
WARNING 2025-04-21 11:40:37,375 log Unauthorized: /api/users/auth/login/
INFO 2025-04-21 11:40:37,862 views Login attempt for email: admin@example.com
INFO 2025-04-21 11:40:40,462 views Registration attempt with data: {'email': 'admin@example.com', 'password': 'newpassword123', 'first_name': 'Duplicate', 'last_name': 'User', 'role': 'client'}
ERROR 2025-04-21 11:40:40,463 views Registration validation errors: {'email': [ErrorDetail(string='user with this email address already exists.', code='unique')]}
WARNING 2025-04-21 11:40:40,463 log Bad Request: /api/users/auth/register/
INFO 2025-04-21 11:40:40,949 views Registration attempt with data: {'email': 'newuser@example.com', 'password': 'newpassword123', 'first_name': 'New', 'last_name': 'User', 'role': 'client'}
WARNING 2025-04-21 11:40:42,105 log Forbidden: /api/users/users/
WARNING 2025-04-21 11:55:31,531 log Forbidden: /api/applications/create-with-cascade/
WARNING 2025-04-21 11:55:31,865 log Not Found: /api/applications/1/signature/
WARNING 2025-04-21 11:55:32,519 log Not Found: /api/applications/applications/99999/
WARNING 2025-04-21 11:55:32,521 log Bad Request: /api/applications/applications/
WARNING 2025-04-21 11:55:32,523 log Bad Request: /api/applications/applications/1/
WARNING 2025-04-21 11:55:32,524 log Unauthorized: /api/applications/applications/
WARNING 2025-04-21 11:55:32,530 log Not Found: /api/applications/applications/2/
INFO 2025-04-21 11:55:34,509 views Login attempt for email: admin@example.com
WARNING 2025-04-21 11:55:35,634 log Bad Request: /api/applications/applications/2/add_fee/
WARNING 2025-04-21 11:55:38,345 log Bad Request: /api/applications/applications/1/add_fee/
WARNING 2025-04-21 11:55:39,662 log Bad Request: /api/applications/applications/1/add_repayment/
WARNING 2025-04-21 11:55:42,327 log Not Found: /api/applications/applications/99999/
WARNING 2025-04-21 11:55:42,328 log Bad Request: /api/applications/applications/
WARNING 2025-04-21 11:55:42,330 log Bad Request: /api/applications/applications/1/
WARNING 2025-04-21 11:55:42,332 log Unauthorized: /api/applications/applications/
INFO 2025-04-21 11:55:47,471 views Login attempt for email: admin@example.com
WARNING 2025-04-21 11:55:47,639 log Unauthorized: /api/users/auth/login/
INFO 2025-04-21 11:55:48,127 views Login attempt for email: admin@example.com
INFO 2025-04-21 11:55:50,744 views Registration attempt with data: {'email': 'admin@example.com', 'password': 'newpassword123', 'first_name': 'Duplicate', 'last_name': 'User', 'role': 'client'}
ERROR 2025-04-21 11:55:50,744 views Registration validation errors: {'email': [ErrorDetail(string='user with this email address already exists.', code='unique')]}
WARNING 2025-04-21 11:55:50,745 log Bad Request: /api/users/auth/register/
INFO 2025-04-21 11:55:51,232 views Registration attempt with data: {'email': 'newuser@example.com', 'password': 'newpassword123', 'first_name': 'New', 'last_name': 'User', 'role': 'client'}
WARNING 2025-04-21 11:55:52,384 log Forbidden: /api/users/users/
WARNING 2025-04-21 12:02:39,046 log Bad Request: /api/applications/validate-schema/
WARNING 2025-04-21 12:02:39,047 log Bad Request: /api/applications/validate-schema/
WARNING 2025-04-21 12:04:19,870 log Bad Request: /api/applications/validate-schema/
WARNING 2025-04-21 12:04:19,872 log Bad Request: /api/applications/validate-schema/
WARNING 2025-04-21 12:05:26,459 log Bad Request: /api/applications/validate-schema/
WARNING 2025-04-21 12:05:26,461 log Bad Request: /api/applications/validate-schema/
WARNING 2025-04-21 12:08:43,461 log Bad Request: /api/applications/validate-schema/
WARNING 2025-04-21 12:08:43,461 log Bad Request: /api/applications/validate-schema/
WARNING 2025-04-21 12:08:53,669 log Bad Request: /api/applications/validate-schema/
WARNING 2025-04-21 12:08:53,670 log Bad Request: /api/applications/validate-schema/
WARNING 2025-04-21 12:11:59,840 log Bad Request: /api/applications/validate-schema/
WARNING 2025-04-21 12:11:59,841 log Bad Request: /api/applications/validate-schema/
WARNING 2025-04-21 12:30:53,964 log Bad Request: /api/applications/applications/1/add_fee/
WARNING 2025-04-21 12:35:49,304 log Bad Request: /api/applications/applications/1/add_fee/
WARNING 2025-04-21 12:36:56,539 log Bad Request: /api/applications/applications/1/add_fee/
WARNING 2025-04-21 12:45:44,265 log Not Found: /api/applications/applications/99999/
WARNING 2025-04-21 12:45:44,267 log Bad Request: /api/applications/applications/
WARNING 2025-04-21 12:45:44,270 log Bad Request: /api/applications/applications/1/
WARNING 2025-04-21 12:45:44,272 log Unauthorized: /api/applications/applications/
WARNING 2025-04-21 12:53:05,879 log Not Found: /api/applications/1/fees/
WARNING 2025-04-21 12:54:56,401 log Not Found: /api/applications/1/fees/
WARNING 2025-04-21 12:55:38,272 log Not Found: /api/applications/1/fees/
WARNING 2025-04-21 12:56:39,647 log Not Found: /api/applications/applications/1/record_payment/
WARNING 2025-04-21 12:58:19,905 log Not Found: /api/applications/applications/99999/
WARNING 2025-04-21 12:58:19,907 log Bad Request: /api/applications/applications/
WARNING 2025-04-21 12:58:19,909 log Bad Request: /api/applications/applications/1/
WARNING 2025-04-21 12:58:19,911 log Unauthorized: /api/applications/applications/
WARNING 2025-04-21 13:03:32,067 log Bad Request: /api/applications/validate-schema/
WARNING 2025-04-21 13:03:32,068 log Bad Request: /api/applications/validate-schema/
WARNING 2025-04-21 13:03:32,906 log Not Found: /api/applications/applications/99999/
WARNING 2025-04-21 13:03:32,907 log Bad Request: /api/applications/applications/
WARNING 2025-04-21 13:03:32,909 log Bad Request: /api/applications/applications/1/
WARNING 2025-04-21 13:03:32,910 log Unauthorized: /api/applications/applications/
WARNING 2025-04-21 13:03:32,916 log Not Found: /api/applications/applications/2/
INFO 2025-04-21 13:03:34,913 views Login attempt for email: admin@example.com
WARNING 2025-04-21 13:03:42,765 log Not Found: /api/applications/applications/99999/
WARNING 2025-04-21 13:03:42,766 log Bad Request: /api/applications/applications/
WARNING 2025-04-21 13:03:42,768 log Bad Request: /api/applications/applications/1/
WARNING 2025-04-21 13:03:42,770 log Unauthorized: /api/applications/applications/
INFO 2025-04-21 13:03:47,941 views Login attempt for email: admin@example.com
WARNING 2025-04-21 13:03:48,104 log Unauthorized: /api/users/auth/login/
INFO 2025-04-21 13:03:48,601 views Login attempt for email: admin@example.com
INFO 2025-04-21 13:03:51,204 views Registration attempt with data: {'email': 'admin@example.com', 'password': 'newpassword123', 'first_name': 'Duplicate', 'last_name': 'User', 'role': 'client'}
ERROR 2025-04-21 13:03:51,205 views Registration validation errors: {'email': [ErrorDetail(string='user with this email address already exists.', code='unique')]}
WARNING 2025-04-21 13:03:51,205 log Bad Request: /api/users/auth/register/
INFO 2025-04-21 13:03:51,692 views Registration attempt with data: {'email': 'newuser@example.com', 'password': 'newpassword123', 'first_name': 'New', 'last_name': 'User', 'role': 'client'}
WARNING 2025-04-21 13:03:52,860 log Forbidden: /api/users/users/
WARNING 2025-04-21 13:04:09,599 log Bad Request: /api/applications/validate-schema/
WARNING 2025-04-21 13:04:09,599 log Bad Request: /api/applications/validate-schema/
WARNING 2025-04-21 13:05:27,099 log Bad Request: /api/applications/validate-schema/
WARNING 2025-04-21 13:05:27,100 log Bad Request: /api/applications/validate-schema/
WARNING 2025-04-21 13:05:27,945 log Not Found: /api/applications/applications/99999/
WARNING 2025-04-21 13:05:27,946 log Bad Request: /api/applications/applications/
WARNING 2025-04-21 13:05:27,948 log Bad Request: /api/applications/applications/1/
WARNING 2025-04-21 13:05:27,950 log Unauthorized: /api/applications/applications/
WARNING 2025-04-21 13:05:27,955 log Not Found: /api/applications/applications/2/
INFO 2025-04-21 13:05:29,969 views Login attempt for email: admin@example.com
WARNING 2025-04-21 13:05:37,673 log Not Found: /api/applications/applications/99999/
WARNING 2025-04-21 13:05:37,674 log Bad Request: /api/applications/applications/
WARNING 2025-04-21 13:05:37,676 log Bad Request: /api/applications/applications/1/
WARNING 2025-04-21 13:05:37,678 log Unauthorized: /api/applications/applications/
INFO 2025-04-21 13:05:42,877 views Login attempt for email: admin@example.com
WARNING 2025-04-21 13:05:43,042 log Unauthorized: /api/users/auth/login/
INFO 2025-04-21 13:05:43,535 views Login attempt for email: admin@example.com
INFO 2025-04-21 13:05:46,174 views Registration attempt with data: {'email': 'admin@example.com', 'password': 'newpassword123', 'first_name': 'Duplicate', 'last_name': 'User', 'role': 'client'}
ERROR 2025-04-21 13:05:46,175 views Registration validation errors: {'email': [ErrorDetail(string='user with this email address already exists.', code='unique')]}
WARNING 2025-04-21 13:05:46,175 log Bad Request: /api/users/auth/register/
INFO 2025-04-21 13:05:46,671 views Registration attempt with data: {'email': 'newuser@example.com', 'password': 'newpassword123', 'first_name': 'New', 'last_name': 'User', 'role': 'client'}
WARNING 2025-04-21 13:05:47,844 log Forbidden: /api/users/users/
WARNING 2025-04-21 13:08:22,558 log Bad Request: /api/applications/validate-schema/
WARNING 2025-04-21 13:08:22,560 log Bad Request: /api/applications/validate-schema/
WARNING 2025-04-21 13:08:23,385 log Not Found: /api/applications/applications/99999/
WARNING 2025-04-21 13:08:23,386 log Bad Request: /api/applications/applications/
WARNING 2025-04-21 13:08:23,388 log Bad Request: /api/applications/applications/1/
WARNING 2025-04-21 13:08:23,389 log Unauthorized: /api/applications/applications/
WARNING 2025-04-21 13:08:23,394 log Not Found: /api/applications/applications/2/
INFO 2025-04-21 13:08:25,428 views Login attempt for email: admin@example.com
WARNING 2025-04-21 13:08:33,315 log Not Found: /api/applications/applications/99999/
WARNING 2025-04-21 13:08:33,316 log Bad Request: /api/applications/applications/
WARNING 2025-04-21 13:08:33,318 log Bad Request: /api/applications/applications/1/
WARNING 2025-04-21 13:08:33,320 log Unauthorized: /api/applications/applications/
INFO 2025-04-21 13:08:38,642 views Login attempt for email: admin@example.com
WARNING 2025-04-21 13:08:38,802 log Unauthorized: /api/users/auth/login/
INFO 2025-04-21 13:08:39,298 views Login attempt for email: admin@example.com
INFO 2025-04-21 13:08:41,918 views Registration attempt with data: {'email': 'admin@example.com', 'password': 'newpassword123', 'first_name': 'Duplicate', 'last_name': 'User', 'role': 'client'}
ERROR 2025-04-21 13:08:41,919 views Registration validation errors: {'email': [ErrorDetail(string='user with this email address already exists.', code='unique')]}
WARNING 2025-04-21 13:08:41,919 log Bad Request: /api/users/auth/register/
INFO 2025-04-21 13:08:42,409 views Registration attempt with data: {'email': 'newuser@example.com', 'password': 'newpassword123', 'first_name': 'New', 'last_name': 'User', 'role': 'client'}
WARNING 2025-04-21 13:08:43,573 log Forbidden: /api/users/users/
WARNING 2025-04-21 13:13:43,504 log Bad Request: /api/applications/validate-schema/
WARNING 2025-04-21 13:13:43,505 log Bad Request: /api/applications/validate-schema/
WARNING 2025-04-21 13:13:44,392 log Not Found: /api/applications/applications/99999/
WARNING 2025-04-21 13:13:44,393 log Bad Request: /api/applications/applications/
WARNING 2025-04-21 13:13:44,396 log Bad Request: /api/applications/applications/1/
WARNING 2025-04-21 13:13:44,397 log Unauthorized: /api/applications/applications/
WARNING 2025-04-21 13:13:44,404 log Not Found: /api/applications/applications/2/
INFO 2025-04-21 13:13:46,573 views Login attempt for email: admin@example.com
WARNING 2025-04-21 13:13:54,908 log Not Found: /api/applications/applications/99999/
WARNING 2025-04-21 13:13:54,910 log Bad Request: /api/applications/applications/
WARNING 2025-04-21 13:13:54,912 log Bad Request: /api/applications/applications/1/
WARNING 2025-04-21 13:13:54,914 log Unauthorized: /api/applications/applications/
INFO 2025-04-21 13:14:00,440 views Login attempt for email: admin@example.com
WARNING 2025-04-21 13:14:00,613 log Unauthorized: /api/users/auth/login/
INFO 2025-04-21 13:14:01,149 views Login attempt for email: admin@example.com
INFO 2025-04-21 13:14:03,918 views Registration attempt with data: {'email': 'admin@example.com', 'password': 'newpassword123', 'first_name': 'Duplicate', 'last_name': 'User', 'role': 'client'}
ERROR 2025-04-21 13:14:03,919 views Registration validation errors: {'email': [ErrorDetail(string='user with this email address already exists.', code='unique')]}
WARNING 2025-04-21 13:14:03,919 log Bad Request: /api/users/auth/register/
INFO 2025-04-21 13:14:04,430 views Registration attempt with data: {'email': 'newuser@example.com', 'password': 'newpassword123', 'first_name': 'New', 'last_name': 'User', 'role': 'client'}
WARNING 2025-04-21 13:14:05,652 log Forbidden: /api/users/users/
INFO 2025-04-21 23:35:47,230 views Login attempt for email: admin@example.com
WARNING 2025-04-21 23:35:47,397 log Unauthorized: /api/users/auth/login/
INFO 2025-04-21 23:35:47,889 views Login attempt for email: admin@example.com
INFO 2025-04-21 23:35:51,149 views Registration attempt with data: {'email': 'newuser@example.com', 'password': 'newpassword123', 'first_name': 'New', 'last_name': 'User', 'role': 'client'}
INFO 2025-04-21 23:35:52,336 views Registration attempt with data: {'email': 'admin@example.com', 'password': 'newpassword123', 'first_name': 'Duplicate', 'last_name': 'User', 'role': 'client'}
ERROR 2025-04-21 23:35:52,337 views Registration validation errors: {'email': [ErrorDetail(string='user with this email address already exists.', code='unique')]}
WARNING 2025-04-21 23:35:52,338 log Bad Request: /api/users/auth/register/
INFO 2025-04-21 23:35:52,838 views Registration attempt with data: {'email': 'newuser@example.com', 'password': 'newpassword123', 'first_name': 'New', 'last_name': 'User', 'role': 'client'}
WARNING 2025-04-21 23:35:54,578 log Forbidden: /api/users/users/
INFO 2025-04-21 23:38:08,761 views Login attempt for email: admin@example.com
WARNING 2025-04-21 23:38:08,927 log Unauthorized: /api/users/auth/login/
INFO 2025-04-21 23:38:09,426 views Login attempt for email: admin@example.com
INFO 2025-04-21 23:38:12,678 views Registration attempt with data: {'email': 'newuser@example.com', 'password': 'newpassword123', 'first_name': 'New', 'last_name': 'User', 'role': 'client'}
INFO 2025-04-21 23:38:13,838 views Registration attempt with data: {'email': 'admin@example.com', 'password': 'newpassword123', 'first_name': 'Duplicate', 'last_name': 'User', 'role': 'client'}
ERROR 2025-04-21 23:38:13,840 views Registration validation errors: {'email': [ErrorDetail(string='user with this email address already exists.', code='unique')]}
WARNING 2025-04-21 23:38:13,840 log Bad Request: /api/users/auth/register/
INFO 2025-04-21 23:38:14,338 views Registration attempt with data: {'email': 'newuser@example.com', 'password': 'newpassword123', 'first_name': 'New', 'last_name': 'User', 'role': 'client'}
WARNING 2025-04-21 23:38:16,067 log Forbidden: /api/users/users/
WARNING 2025-04-22 00:16:07,821 log Not Found: /api/applications/applications/99999/
WARNING 2025-04-22 00:16:07,822 log Forbidden: /api/applications/applications/
WARNING 2025-04-22 00:16:08,329 log Not Found: /api/applications/1/signature/
WARNING 2025-04-22 00:16:08,835 log Not Found: /api/applications/99999/signature/
WARNING 2025-04-22 00:16:09,338 log Not Found: /api/applications/1/signature/
WARNING 2025-04-22 00:16:09,840 log Bad Request: /api/applications/applications/validate_schema/
WARNING 2025-04-22 00:16:10,356 log Bad Request: /api/applications/applications/validate_schema/
WARNING 2025-04-22 00:24:19,229 log Not Found: /api/applications/applications/99999/
WARNING 2025-04-22 00:24:19,230 log Forbidden: /api/applications/applications/
WARNING 2025-04-22 00:24:19,737 log Bad Request: /api/applications/1/signature/
WARNING 2025-04-22 00:24:20,236 log Not Found: /api/applications/99999/signature/
WARNING 2025-04-22 00:24:21,252 log Bad Request: /api/applications/validate-schema/
WARNING 2025-04-22 00:24:21,751 log Bad Request: /api/applications/validate-schema/
WARNING 2025-04-22 00:25:22,116 log Not Found: /api/applications/applications/99999/
WARNING 2025-04-22 00:25:22,116 log Forbidden: /api/applications/applications/
WARNING 2025-04-22 00:25:22,117 log Forbidden: /api/applications/applications/1/
WARNING 2025-04-22 00:25:22,615 log Bad Request: /api/applications/1/signature/
WARNING 2025-04-22 00:25:23,110 log Not Found: /api/applications/99999/signature/
WARNING 2025-04-22 00:25:24,124 log Bad Request: /api/applications/validate-schema/
WARNING 2025-04-22 00:25:24,626 log Bad Request: /api/applications/validate-schema/
WARNING 2025-04-22 00:26:15,874 log Not Found: /api/applications/applications/99999/
WARNING 2025-04-22 00:26:15,874 log Forbidden: /api/applications/applications/
WARNING 2025-04-22 00:26:15,874 log Forbidden: /api/applications/applications/1/
WARNING 2025-04-22 00:26:15,876 log Unauthorized: /api/applications/applications/
WARNING 2025-04-22 00:26:16,370 log Bad Request: /api/applications/1/signature/
WARNING 2025-04-22 00:26:16,866 log Not Found: /api/applications/99999/signature/
WARNING 2025-04-22 00:26:17,877 log Bad Request: /api/applications/validate-schema/
WARNING 2025-04-22 00:26:18,372 log Bad Request: /api/applications/validate-schema/
WARNING 2025-04-22 00:29:54,986 log Not Found: /api/borrowers/1/applications/
WARNING 2025-04-22 00:29:55,495 log Not Found: /api/borrowers/1/guarantors/
ERROR 2025-04-22 00:29:56,514 log Internal Server Error: /api/borrowers/
Traceback (most recent call last):
  File "/Users/hongyuanfan/Library/Python/3.9/lib/python/site-packages/django/core/handlers/exception.py", line 55, in inner
    response = get_response(request)
  File "/Users/hongyuanfan/Library/Python/3.9/lib/python/site-packages/django/core/handlers/base.py", line 197, in _get_response
    response = wrapped_callback(request, *callback_args, **callback_kwargs)
  File "/Users/hongyuanfan/Library/Python/3.9/lib/python/site-packages/django/views/decorators/csrf.py", line 56, in wrapper_view
    return view_func(*args, **kwargs)
  File "/Users/hongyuanfan/Library/Python/3.9/lib/python/site-packages/rest_framework/viewsets.py", line 125, in view
    return self.dispatch(request, *args, **kwargs)
  File "/Users/hongyuanfan/Library/Python/3.9/lib/python/site-packages/rest_framework/views.py", line 509, in dispatch
    response = self.handle_exception(exc)
  File "/Users/hongyuanfan/Library/Python/3.9/lib/python/site-packages/rest_framework/views.py", line 469, in handle_exception
    self.raise_uncaught_exception(exc)
  File "/Users/hongyuanfan/Library/Python/3.9/lib/python/site-packages/rest_framework/views.py", line 480, in raise_uncaught_exception
    raise exc
  File "/Users/hongyuanfan/Library/Python/3.9/lib/python/site-packages/rest_framework/views.py", line 506, in dispatch
    response = handler(request, *args, **kwargs)
  File "/Users/hongyuanfan/Library/Python/3.9/lib/python/site-packages/rest_framework/mixins.py", line 43, in list
    return self.get_paginated_response(serializer.data)
  File "/Users/hongyuanfan/Library/Python/3.9/lib/python/site-packages/rest_framework/serializers.py", line 768, in data
    ret = super().data
  File "/Users/hongyuanfan/Library/Python/3.9/lib/python/site-packages/rest_framework/serializers.py", line 253, in data
    self._data = self.to_representation(self.instance)
  File "/Users/hongyuanfan/Library/Python/3.9/lib/python/site-packages/rest_framework/serializers.py", line 686, in to_representation
    return [
  File "/Users/hongyuanfan/Library/Python/3.9/lib/python/site-packages/rest_framework/serializers.py", line 687, in <listcomp>
    self.child.to_representation(item) for item in iterable
  File "/Users/hongyuanfan/Library/Python/3.9/lib/python/site-packages/rest_framework/serializers.py", line 522, in to_representation
    ret[field.field_name] = field.to_representation(attribute)
  File "/Users/hongyuanfan/Library/Python/3.9/lib/python/site-packages/rest_framework/fields.py", line 1838, in to_representation
    return method(value)
  File "/Users/hongyuanfan/Desktop/LoanAPPV3/backenddjango/borrowers/serializers.py", line 18, in get_application_count
    return obj.applications.count()
AttributeError: 'Borrower' object has no attribute 'applications'
WARNING 2025-04-22 00:29:57,031 log Forbidden: /api/borrowers/
WARNING 2025-04-22 00:29:57,530 log Forbidden: /api/borrowers/1/
WARNING 2025-04-22 00:29:58,022 log Not Found: /api/borrowers/1/
WARNING 2025-04-22 00:29:59,031 log Forbidden: /api/borrowers/1/
WARNING 2025-04-22 00:29:59,364 log Not Found: /api/borrowers/guarantors/
WARNING 2025-04-22 00:29:59,692 log Method Not Allowed: /api/borrowers/guarantors/
WARNING 2025-04-22 00:30:00,024 log Method Not Allowed: /api/borrowers/guarantors/
WARNING 2025-04-22 00:30:00,367 log Forbidden: /api/borrowers/guarantors/1/
WARNING 2025-04-22 00:30:00,705 log Not Found: /api/borrowers/guarantors/1/
WARNING 2025-04-22 00:30:01,042 log Method Not Allowed: /api/borrowers/guarantors/
WARNING 2025-04-22 00:30:01,371 log Not Found: /api/borrowers/guarantors/
WARNING 2025-04-22 00:30:01,701 log Forbidden: /api/borrowers/guarantors/1/
WARNING 2025-04-22 00:50:01,867 log Not Found: /api/borrowers/1/applications/
WARNING 2025-04-22 00:50:02,357 log Not Found: /api/borrowers/1/guarantors/
WARNING 2025-04-22 00:50:03,354 log Not Found: /api/borrowers/1/
WARNING 2025-04-22 00:50:03,848 log Forbidden: /api/borrowers/
WARNING 2025-04-22 00:50:04,332 log Forbidden: /api/borrowers/1/
WARNING 2025-04-22 00:50:04,824 log Not Found: /api/borrowers/1/
WARNING 2025-04-22 00:50:05,823 log Forbidden: /api/borrowers/1/
WARNING 2025-04-22 00:50:06,152 log Not Found: /api/borrowers/guarantors/
WARNING 2025-04-22 00:50:06,482 log Method Not Allowed: /api/borrowers/guarantors/
WARNING 2025-04-22 00:50:06,808 log Method Not Allowed: /api/borrowers/guarantors/
WARNING 2025-04-22 00:50:07,134 log Forbidden: /api/borrowers/guarantors/1/
WARNING 2025-04-22 00:50:07,462 log Not Found: /api/borrowers/guarantors/1/
WARNING 2025-04-22 00:50:07,790 log Method Not Allowed: /api/borrowers/guarantors/
WARNING 2025-04-22 00:50:07,791 log Method Not Allowed: /api/borrowers/guarantors/
WARNING 2025-04-22 00:50:08,121 log Not Found: /api/borrowers/guarantors/
WARNING 2025-04-22 00:50:08,122 log Not Found: /api/borrowers/guarantors/
WARNING 2025-04-22 00:50:08,446 log Forbidden: /api/borrowers/guarantors/1/
WARNING 2025-04-22 00:52:43,032 log Not Found: /api/borrowers/1/applications/
WARNING 2025-04-22 00:52:43,540 log Not Found: /api/borrowers/1/guarantors/
WARNING 2025-04-22 00:52:44,554 log Not Found: /api/borrowers/1/
WARNING 2025-04-22 00:52:45,052 log Forbidden: /api/borrowers/
WARNING 2025-04-22 00:52:45,549 log Forbidden: /api/borrowers/1/
WARNING 2025-04-22 00:52:46,045 log Not Found: /api/borrowers/1/
WARNING 2025-04-22 00:52:47,035 log Forbidden: /api/borrowers/1/
WARNING 2025-04-22 00:52:47,366 log Not Found: /api/borrowers/guarantors/
WARNING 2025-04-22 00:52:47,696 log Method Not Allowed: /api/borrowers/guarantors/
WARNING 2025-04-22 00:52:48,028 log Method Not Allowed: /api/borrowers/guarantors/
WARNING 2025-04-22 00:52:48,367 log Forbidden: /api/borrowers/guarantors/1/
WARNING 2025-04-22 00:52:48,704 log Not Found: /api/borrowers/guarantors/1/
WARNING 2025-04-22 00:52:49,034 log Method Not Allowed: /api/borrowers/guarantors/
WARNING 2025-04-22 00:52:49,035 log Method Not Allowed: /api/borrowers/guarantors/
WARNING 2025-04-22 00:52:49,365 log Not Found: /api/borrowers/guarantors/
WARNING 2025-04-22 00:52:49,693 log Forbidden: /api/borrowers/guarantors/1/
WARNING 2025-04-22 00:54:11,053 log Not Found: /api/borrowers/1/applications/
WARNING 2025-04-22 00:54:11,552 log Not Found: /api/borrowers/1/guarantors/
WARNING 2025-04-22 00:54:12,543 log Not Found: /api/borrowers/1/
WARNING 2025-04-22 00:54:13,029 log Forbidden: /api/borrowers/
WARNING 2025-04-22 00:54:13,522 log Forbidden: /api/borrowers/1/
WARNING 2025-04-22 00:54:14,013 log Not Found: /api/borrowers/1/
WARNING 2025-04-22 00:54:14,991 log Forbidden: /api/borrowers/1/
WARNING 2025-04-22 00:54:15,319 log Not Found: /api/borrowers/guarantors/
WARNING 2025-04-22 00:54:15,641 log Method Not Allowed: /api/borrowers/guarantors/
WARNING 2025-04-22 00:54:15,967 log Method Not Allowed: /api/borrowers/guarantors/
WARNING 2025-04-22 00:54:16,289 log Forbidden: /api/borrowers/guarantors/1/
WARNING 2025-04-22 00:54:16,620 log Not Found: /api/borrowers/guarantors/1/
WARNING 2025-04-22 00:54:16,944 log Method Not Allowed: /api/borrowers/guarantors/
WARNING 2025-04-22 00:54:16,944 log Method Not Allowed: /api/borrowers/guarantors/
WARNING 2025-04-22 00:54:17,274 log Not Found: /api/borrowers/guarantors/
WARNING 2025-04-22 00:54:17,600 log Forbidden: /api/borrowers/guarantors/1/
